Workbook
Name Company_Name: Inputs!$E$5
Name Base_Year: Inputs!$E$7
Name Valuation_Date: Inputs!$E$8
Name Forecast_Years: Inputs!$E$11
Name Discounting: Inputs!$E$12
Name Scenario: Inputs!$E$13
Name FCF_Source: Inputs!$E$14
Name WACC_Source: Inputs!$E$15
Name TV_Method: Inputs!$E$16
Name Mid_Year: Inputs!$E$19
Name Scenario_No: Inputs!$E$20
Name Build_Flag: Inputs!$E$21
Name Exit_Flag: Inputs!$E$22
Name Base_FCF: Inputs!$E$25
Name FCF_Growth: Inputs!$E$26
Name Base_Revenue: Inputs!$E$29
Name Tax_Rate: Inputs!$E$30
Name DA_Pct: Inputs!$E$31
Name Capex_Pct: Inputs!$E$32
Name NWC_Pct: Inputs!$E$33
Name Live_Growth: Inputs!$F$41:$J$41
Name Live_Margin: Inputs!$F$47:$J$47
Name Exit_Multiple: Inputs!$E$53
Name WACC_Direct: Inputs!$E$56
Name Rf: Inputs!$E$57
Name Beta_Type: Inputs!$E$58
Name Beta_Input: Inputs!$E$59
Name MRP: Inputs!$E$60
Name Cost_Of_Debt: Inputs!$E$61
Name Target_DV: Inputs!$E$62
Name TGR: Inputs!$E$65
Name Cash: Inputs!$E$68
Name Debt: Inputs!$E$69
Name Minorities: Inputs!$E$70
Name Investments: Inputs!$E$71
Name Pensions: Inputs!$E$72
Name Shares: Inputs!$E$73
Name Share_Price: Inputs!$E$74
Name Step_WACC: Settings!$E$5
Name Step_TGR: Settings!$E$6
Name Step_Multiple: Settings!$E$7
Name Growth_Lower: Settings!$E$8
Name Growth_Upper: Settings!$E$9
Name WACC_Lower: Settings!$E$10
Name WACC_Upper: Settings!$E$11
Name WACC_Spread: Settings!$E$12
Name Check_Tolerance: Settings!$E$13
Name Reverse_Tolerance: Settings!$E$14
Name TV_Share_Limit: Settings!$E$15
Name FCF_Used: 'FCF Build'!$F$29:$O$29
Name EBITDA_Used: 'FCF Build'!$F$30:$O$30
Name WACC_CAPM: WACC!$E$21
Name WACC: WACC!$E$24
Name In_Forecast: DCF!$F$6:$O$6
Name Disc_Period: DCF!$F$10:$O$10
Name FCF_N: DCF!$E$16
Name EBITDA_N: DCF!$E$17
Name TV_Perp: DCF!$E$19
Name TV_Exit: DCF!$E$21
Name PV_TV: DCF!$E$25

Sheet Cover
B1: Swiss DCF Model
B2: =IF(Company_Name="","Company not specified",Company_Name)&" | CHF m unless stated otherwise | Scenario: "&IF(Build_Flag=1,Scenario,"not used (direct FCF)")&" | Checks: "&Check_Status
B4: About this file
B5: Version | C5: v1.0.0
B6: Created | C6: 20 October 2026
B7: File | C7: Blank template (fill in the blue cells on the sheet Inputs)
B8: Currency and units | C8: CHF. Amounts in millions, shares in millions, price per share in CHF
B9: Company | C9: =IF(Company_Name="","(not specified)",Company_Name)
B11: Key results
B12: Model status | C12: =Check_Status
B13: Value per share (CHF) | C13: =Value_Per_Share
B14: Current share price (CHF) | C14: =Share_Price
B15: Implied growth, years 1 to 5 | C15: =Implied_Growth
B16: WACC used in the model | C16: =IF(Inputs_OK=1,WACC,"n/a")
B17: Comparison: WACC (CAPM) | C17: =IF(AND(COUNT(Rf,Beta_Input,MRP)=3,COUNT(Cost_Of_Debt,Target_DV,Tax_Rate)=3),WACC_CAPM,"n/a")
B18: Comparison: implied WACC | C18: =Implied_WACC
B20: Colour code
B21: 1.0 | C21: Blue: input
B22: 1.0 | C22: Black: formula
B23: 1.0 | C23: Green: link to another sheet
B25: Contents
B26: Inputs | C26: Assumptions and switches: scenario, FCF and WACC source, terminal value, conventions
B27: FCF Build | C27: Unlevered free cash flow from EBIT, or from direct input
B28: WACC | C28: CAPM cost of equity, after-tax cost of debt, target capital structure
B29: DCF | C29: Discounting, terminal value, cross-checks and equity bridge
B30: Sensitivities | C30: Value per share for WACC, terminal growth and exit multiple
B31: Reverse DCF | C31: Growth and WACC implied by the share price, solved with visible formulas
B32: Checks | C32: Plausibility and integrity checks
B33: Settings | C33: Technical parameters: search bounds, tolerances, sensitivity steps
B35: Sources and licence
B36: Risk-free rate | C36: Swiss National Bank, data portal, table rendeiduebm: spot interest rate of the 10-year Swiss Confederation bond, end of month. Suggested value 0.586% (September 2026)
B37: Method | C37: https://noelwalpert.com/tools/dcf-rechner (section "Für Fachleute")
B38: Repository | C38: https://github.com/noelwalpert/swiss-financial-models
B39: Licence | C39: CC BY 4.0. You may share and adapt this file, also commercially, if you credit: Noel Walpert, noelwalpert.com
B41: Disclaimer
B42: This model is an illustration for educational and informational purposes. It is not investment, legal or tax advice and not a recommendation to buy or sell any security. The value per share is a calculated value based on your own assumptions, not a fair value and not a price target. Results depend entirely on the inputs.

Sheet Inputs
B1: Inputs
B2: =IF(Company_Name="","Company not specified",Company_Name)&" | CHF m unless stated otherwise | Scenario: "&IF(Build_Flag=1,Scenario,"not used (direct FCF)")&" | Checks: "&Check_Status
B4: General
B5: Company name
B6: Currency | E6: CHF
B7: Base fiscal year | C7: year
B8: Valuation date | C8: date | E8: =IF(ISNUMBER(Base_Year),DATE(Base_Year,12,31),"n/a")
B10: Model switches
B11: Forecast period | C11: years | E11: 5
B12: Discounting convention | E12: Year-end
B13: Scenario | E13: Base
B14: Free cash flow source | E14: Direct
B15: WACC source | E15: Direct
B16: Terminal value method | E16: Perpetuity growth
B18: Derived switch values
B19: Mid-year shift | C19: years | E19: =IF(Discounting="Mid-year",0.5,0)
B20: Scenario number | C20: 1 to 3 | E20: =IF(Scenario="Bear",1,IF(Scenario="Bull",3,2))
B21: FCF build flag | C21: 1 = build | E21: =IF(FCF_Source="Build",1,0)
B22: Exit multiple flag | C22: 1 = exit | E22: =IF(TV_Method="Exit multiple",1,0)
B24: Free cash flow, direct input
B25: Free cash flow, base year | C25: CHF m
B26: FCF growth, years 1 to 5 | C26: % p.a.
B28: Free cash flow build, operating assumptions
B29: Revenue, base year | C29: CHF m
B30: Tax rate on EBIT | C30: %
B31: Depreciation and amortisation | C31: % of revenue
B32: Capital expenditure | C32: % of revenue
B33: Net working capital | C33: % of revenue
B35: Scenarios for the FCF build
E36: Value | F36: Year 1 | G36: Year 2 | H36: Year 3 | I36: Year 4 | J36: Year 5
B37: Revenue growth
B38: Bear | C38: %
B39: Base | C39: %
B40: Bull | C40: %
B41: Live (selected scenario) | C41: % | F41: =CHOOSE(Scenario_No,F38,F39,F40) | G41: =CHOOSE(Scenario_No,G38,G39,G40) | H41: =CHOOSE(Scenario_No,H38,H39,H40) | I41: =CHOOSE(Scenario_No,I38,I39,I40) | J41: =CHOOSE(Scenario_No,J38,J39,J40)
B43: EBIT margin
B44: Bear | C44: %
B45: Base | C45: %
B46: Bull | C46: %
B47: Live (selected scenario) | C47: % | F47: =CHOOSE(Scenario_No,F44,F45,F46) | G47: =CHOOSE(Scenario_No,G44,G45,G46) | H47: =CHOOSE(Scenario_No,H44,H45,H46) | I47: =CHOOSE(Scenario_No,I44,I45,I46) | J47: =CHOOSE(Scenario_No,J44,J45,J46)
...

Sheet FCF Build
B1: FCF Build
B2: =IF(Company_Name="","Company not specified",Company_Name)&" | CHF m unless stated otherwise | Scenario: "&IF(Build_Flag=1,Scenario,"not used (direct FCF)")&" | Checks: "&Check_Status
B4: Year | C4: t | E4: =0 | F4: =E4+1 | G4: =F4+1 | H4: =G4+1 | I4: =H4+1 | J4: =I4+1 | K4: =J4+1 | L4: =K4+1 | M4: =L4+1 | ... O4: =N4+1
B5: Fiscal year | C5: FY | E5: =IF(ISNUMBER(Base_Year),Base_Year+E4,E4) | F5: =IF(ISNUMBER(Base_Year),Base_Year+F4,F4) | G5: =IF(ISNUMBER(Base_Year),Base_Year+G4,G4) | H5: =IF(ISNUMBER(Base_Year),Base_Year+H4,H4) | I5: =IF(ISNUMBER(Base_Year),Base_Year+I4,I4) | J5: =IF(ISNUMBER(Base_Year),Base_Year+J4,J4) | K5: =IF(ISNUMBER(Base_Year),Base_Year+K4,K4) | L5: =IF(ISNUMBER(Base_Year),Base_Year+L4,L4) | ... O5: =IF(ISNUMBER(Base_Year),Base_Year+O4,O4)
B6: In forecast period | C6: 1 = yes | E6: =IF(E4<=Forecast_Years,1,0) | F6: =IF(F4<=Forecast_Years,1,0) | G6: =IF(G4<=Forecast_Years,1,0) | H6: =IF(H4<=Forecast_Years,1,0) | I6: =IF(I4<=Forecast_Years,1,0) | J6: =IF(J4<=Forecast_Years,1,0) | K6: =IF(K4<=Forecast_Years,1,0) | L6: =IF(L4<=Forecast_Years,1,0) | ... O6: =IF(O4<=Forecast_Years,1,0)
B8: Free cash flow build from EBIT
B9: Revenue growth | C9: % | F9: =Inputs!F41 | G9: =Inputs!G41 | H9: =Inputs!H41 | I9: =Inputs!I41 | J9: =Inputs!J41 | K9: =$J9+(TGR-$J9)*(K$4-5)/5 | L9: =$J9+(TGR-$J9)*(L$4-5)/5 | M9: =$J9+(TGR-$J9)*(M$4-5)/5 | N9: =$J9+(TGR-$J9)*(N$4-5)/5 | O9: =$J9+(TGR-$J9)*(O$4-5)/5
B10: Revenue | C10: CHF m | E10: =Base_Revenue | F10: =E10*(1+F9) | G10: =F10*(1+G9) | H10: =G10*(1+H9) | I10: =H10*(1+I9) | J10: =I10*(1+J9) | K10: =J10*(1+K9) | L10: =K10*(1+L9) | M10: =L10*(1+M9) | ... O10: =N10*(1+O9)
B11: EBIT margin | C11: % | F11: =Inputs!F47 | G11: =Inputs!G47 | H11: =Inputs!H47 | I11: =Inputs!I47 | J11: =Inputs!J47 | K11: =$J11 | L11: =$J11 | M11: =$J11 | N11: =$J11 | O11: =$J11
B12: EBIT | C12: CHF m | F12: =F10*F11 | G12: =G10*G11 | H12: =H10*H11 | I12: =I10*I11 | J12: =J10*J11 | K12: =K10*K11 | L12: =L10*L11 | M12: =M10*M11 | ... O12: =O10*O11
B13: Less taxes on EBIT | C13: CHF m | F13: =-F12*Tax_Rate | G13: =-G12*Tax_Rate | H13: =-H12*Tax_Rate | I13: =-I12*Tax_Rate | J13: =-J12*Tax_Rate | K13: =-K12*Tax_Rate | L13: =-L12*Tax_Rate | M13: =-M12*Tax_Rate | ... O13: =-O12*Tax_Rate
B14: NOPAT | C14: CHF m | F14: =F12+F13 | G14: =G12+G13 | H14: =H12+H13 | I14: =I12+I13 | J14: =J12+J13 | K14: =K12+K13 | L14: =L12+L13 | M14: =M12+M13 | ... O14: =O12+O13
B15: Plus depreciation and amortisation | C15: CHF m | F15: =F10*DA_Pct | G15: =G10*DA_Pct | H15: =H10*DA_Pct | I15: =I10*DA_Pct | J15: =J10*DA_Pct | K15: =K10*DA_Pct | L15: =L10*DA_Pct | M15: =M10*DA_Pct | ... O15: =O10*DA_Pct
B16: Less capital expenditure | C16: CHF m | F16: =-F10*Capex_Pct | G16: =-G10*Capex_Pct | H16: =-H10*Capex_Pct | I16: =-I10*Capex_Pct | J16: =-J10*Capex_Pct | K16: =-K10*Capex_Pct | L16: =-L10*Capex_Pct | M16: =-M10*Capex_Pct | ... O16: =-O10*Capex_Pct
B17: Net working capital | C17: CHF m | E17: =E10*NWC_Pct | F17: =F10*NWC_Pct | G17: =G10*NWC_Pct | H17: =H10*NWC_Pct | I17: =I10*NWC_Pct | J17: =J10*NWC_Pct | K17: =K10*NWC_Pct | L17: =L10*NWC_Pct | ... O17: =O10*NWC_Pct
B18: Less increase in net working capital | C18: CHF m | F18: =-(F17-E17) | G18: =-(G17-F17) | H18: =-(H17-G17) | I18: =-(I17-H17) | J18: =-(J17-I17) | K18: =-(K17-J17) | L18: =-(L17-K17) | M18: =-(M17-L17) | ... O18: =-(O17-N17)
B19: Unlevered free cash flow (build) | C19: CHF m | F19: =F14+F15+F16+F18 | G19: =G14+G15+G16+G18 | H19: =H14+H15+H16+H18 | I19: =I14+I15+I16+I18 | J19: =J14+J15+J16+J18 | K19: =K14+K15+K16+K18 | L19: =L14+L15+L16+L18 | M19: =M14+M15+M16+M18 | ... O19: =O14+O15+O16+O18
B20: EBITDA | C20: CHF m | F20: =F12+F15 | G20: =G12+G15 | H20: =H12+H15 | I20: =I12+I15 | J20: =J12+J15 | K20: =K12+K15 | L20: =L12+L15 | M20: =M12+M15 | ... O20: =O12+O15
B21: Memo: FCF margin | C21: % | F21: =IF(F10<>0,F19/F10,0) | G21: =IF(G10<>0,G19/G10,0) | H21: =IF(H10<>0,H19/H10,0) | I21: =IF(I10<>0,I19/I10,0) | J21: =IF(J10<>0,J19/J10,0) | K21: =IF(K10<>0,K19/K10,0) | L21: =IF(L10<>0,L19/L10,0) | M21: =IF(M10<>0,M19/M10,0) | ... O21: =IF(O10<>0,O19/O10,0)
B22: Memo: capex / D&A | C22: x | F22: =IF(F15<>0,-F16/F15,0) | G22: =IF(G15<>0,-G16/G15,0) | H22: =IF(H15<>0,-H16/H15,0) | I22: =IF(I15<>0,-I16/I15,0) | J22: =IF(J15<>0,-J16/J15,0) | K22: =IF(K15<>0,-K16/K15,0) | L22: =IF(L15<>0,-L16/L15,0) | M22: =IF(M15<>0,-M16/M15,0) | ... O22: =IF(O15<>0,-O16/O15,0)
B24: Free cash flow, direct input
B25: FCF growth | C25: % | F25: =FCF_Growth | G25: =FCF_Growth | H25: =FCF_Growth | I25: =FCF_Growth | J25: =FCF_Growth | K25: =$J25+(TGR-$J25)*(K$4-5)/5 | L25: =$J25+(TGR-$J25)*(L$4-5)/5 | M25: =$J25+(TGR-$J25)*(M$4-5)/5 | N25: =$J25+(TGR-$J25)*(N$4-5)/5 | O25: =$J25+(TGR-$J25)*(O$4-5)/5
B26: Free cash flow (direct) | C26: CHF m | E26: =Base_FCF | F26: =E26*(1+F25) | G26: =F26*(1+G25) | H26: =G26*(1+H25) | I26: =H26*(1+I25) | J26: =I26*(1+J25) | K26: =J26*(1+K25) | L26: =K26*(1+L25) | M26: =L26*(1+M25) | ... O26: =N26*(1+O25)
B28: Selected for the valuation
B29: Free cash flow used in the DCF | C29: CHF m | F29: =IF(Build_Flag=1,F19,F26) | G29: =IF(Build_Flag=1,G19,G26) | H29: =IF(Build_Flag=1,H19,H26) | I29: =IF(Build_Flag=1,I19,I26) | J29: =IF(Build_Flag=1,J19,J26) | K29: =IF(Build_Flag=1,K19,K26) | L29: =IF(Build_Flag=1,L19,L26) | M29: =IF(Build_Flag=1,M19,M26) | ... O29: =IF(Build_Flag=1,O19,O26)
B30: EBITDA used for the exit multiple | C30: CHF m | F30: =IF(Build_Flag=1,F20,0) | G30: =IF(Build_Flag=1,G20,0) | H30: =IF(Build_Flag=1,H20,0) | I30: =IF(Build_Flag=1,I20,0) | J30: =IF(Build_Flag=1,J20,0) | K30: =IF(Build_Flag=1,K20,0) | L30: =IF(Build_Flag=1,L20,0) | M30: =IF(Build_Flag=1,M20,0) | ... O30: =IF(Build_Flag=1,O20,0)

Sheet WACC
B1: WACC
B2: =IF(Company_Name="","Company not specified",Company_Name)&" | CHF m unless stated otherwise | Scenario: "&IF(Build_Flag=1,Scenario,"not used (direct FCF)")&" | Checks: "&Check_Status
B4: Cost of equity (CAPM)
B5: Risk-free rate | C5: % | E5: =Rf
B6: Beta input type | E6: =Beta_Type
B7: Beta input | E7: =Beta_Input
B8: Target debt / total capital (D/V) | C8: % | E8: =Target_DV
B9: Equity / total capital (E/V) | C9: % | E9: =1-E8
B10: Debt / equity (D/E) | C10: x | E10: =IF(E9>0,E8/E9,0)
B11: Tax rate | C11: % | E11: =Tax_Rate
B12: Levered beta | E12: =IF(E6="Unlevered",E7*(1+(1-E11)*E10),E7)
B13: Market risk premium | C13: % | E13: =MRP
B14: Cost of equity | C14: % | D14: Rf + beta x MRP | E14: =E5+E12*E13
B16: Cost of debt
B17: Pre-tax cost of debt | C17: % | E17: =Cost_Of_Debt
B18: After-tax cost of debt | C18: % | E18: =E17*(1-E11)
B20: WACC
B21: WACC (CAPM) | C21: % | D21: E/V x Ke + D/V x Kd x (1 - t) | E21: =E9*E14+E8*E18
B22: WACC (direct input) | C22: % | E22: =WACC_Direct
B23: WACC source | E23: =WACC_Source
B24: WACC used in the model | C24: % | E24: =IF(E23="CAPM",E21,E22)
B26: Comparison
B27: WACC implied by the current share price | C27: % | E27: =Implied_WACC
B28: CAPM WACC less implied WACC | C28: % | E28: =IF(ISNUMBER(E27),E21-E27,"n/a")

Sheet DCF
B1: DCF
B2: =IF(Company_Name="","Company not specified",Company_Name)&" | CHF m unless stated otherwise | Scenario: "&IF(Build_Flag=1,Scenario,"not used (direct FCF)")&" | Checks: "&Check_Status
B4: Year | C4: t | E4: ='FCF Build'!E4 | F4: ='FCF Build'!F4 | G4: ='FCF Build'!G4 | H4: ='FCF Build'!H4 | I4: ='FCF Build'!I4 | J4: ='FCF Build'!J4 | K4: ='FCF Build'!K4 | L4: ='FCF Build'!L4 | ... O4: ='FCF Build'!O4
B5: Fiscal year | C5: FY | E5: ='FCF Build'!E5 | F5: ='FCF Build'!F5 | G5: ='FCF Build'!G5 | H5: ='FCF Build'!H5 | I5: ='FCF Build'!I5 | J5: ='FCF Build'!J5 | K5: ='FCF Build'!K5 | L5: ='FCF Build'!L5 | ... O5: ='FCF Build'!O5
B6: In forecast period | C6: 1 = yes | E6: ='FCF Build'!E6 | F6: ='FCF Build'!F6 | G6: ='FCF Build'!G6 | H6: ='FCF Build'!H6 | I6: ='FCF Build'!I6 | J6: ='FCF Build'!J6 | K6: ='FCF Build'!K6 | L6: ='FCF Build'!L6 | ... O6: ='FCF Build'!O6
B8: Discounted cash flow
B9: Free cash flow | C9: CHF m | F9: ='FCF Build'!F29 | G9: ='FCF Build'!G29 | H9: ='FCF Build'!H29 | I9: ='FCF Build'!I29 | J9: ='FCF Build'!J29 | K9: ='FCF Build'!K29 | L9: ='FCF Build'!L29 | M9: ='FCF Build'!M29 | ... O9: ='FCF Build'!O29
B10: Discount period | C10: years | F10: =F4-Mid_Year | G10: =G4-Mid_Year | H10: =H4-Mid_Year | I10: =I4-Mid_Year | J10: =J4-Mid_Year | K10: =K4-Mid_Year | L10: =L4-Mid_Year | M10: =M4-Mid_Year | ... O10: =O4-Mid_Year
B11: Discount factor | D11: 1 / (1 + WACC) ^ period | F11: =1/(1+WACC)^F10 | G11: =1/(1+WACC)^G10 | H11: =1/(1+WACC)^H10 | I11: =1/(1+WACC)^I10 | J11: =1/(1+WACC)^J10 | K11: =1/(1+WACC)^K10 | L11: =1/(1+WACC)^L10 | M11: =1/(1+WACC)^M10 | ... O11: =1/(1+WACC)^O10
B12: Present value of free cash flow | C12: CHF m | F12: =F9*F11*F6 | G12: =G9*G11*G6 | H12: =H9*H11*H6 | I12: =I9*I11*I6 | J12: =J9*J11*J6 | K12: =K9*K11*K6 | L12: =L9*L11*L6 | M12: =M9*M11*M6 | ... O12: =O9*O11*O6
B14: Terminal value
B15: Final forecast year (N) | C15: year | E15: =Forecast_Years
B16: Free cash flow in year N | C16: CHF m | E16: =INDEX($F$9:$O$9,1,E15)
B17: EBITDA in year N | C17: CHF m | E17: =INDEX('FCF Build'!$F$30:$O$30,1,E15)
B18: Terminal growth rate | C18: % | E18: =TGR
B19: Terminal value, perpetuity growth | C19: CHF m | D19: FCF(N) x (1 + g) / (WACC - g) | E19: =IF(E18<WACC,E16*(1+E18)/(WACC-E18),0)
B20: Exit multiple (EV / EBITDA) | C20: x | E20: =Exit_Multiple
B21: Terminal value, exit multiple | C21: CHF m | D21: EBITDA(N) x exit multiple | E21: =E17*E20
B22: Terminal value method | E22: =TV_Method
B23: Terminal value used | C23: CHF m | E23: =IF(Exit_Flag=1,E21,E19)
B24: Discount period of terminal value | C24: years | E24: =IF(Exit_Flag=1,E15,E15-Mid_Year)
B25: Present value of terminal value | C25: CHF m | E25: =E23/(1+WACC)^E24
B27: Cross-checks
B28: Implied exit multiple from perpetuity growth | C28: x | E28: =IF(AND(Build_Flag=1,E17>0,E18<WACC),E19/E17,"n/a")
B29: Implied terminal growth from exit multiple | C29: % | E29: =IF(AND(Build_Flag=1,E21+E16*(1+WACC)^Mid_Year<>0),(E21*WACC-E16*(1+WACC)^Mid_Year)/(E21+E16*(1+WACC)^Mid_Year),"n/a")
B31: Enterprise value to equity value
B32: Sum of present values of free cash flows | C32: CHF m | E32: =SUM(F12:O12)
B33: Present value of terminal value | C33: CHF m | E33: =E25
B34: Enterprise value | C34: CHF m | E34: =E32+E33
B35: Plus cash and cash equivalents | C35: CHF m | E35: =Cash
B36: Less financial debt | C36: CHF m | E36: =-Debt
B37: Less minority interests | C37: CHF m | E37: =-Minorities
B38: Plus non-operating investments | C38: CHF m | E38: =Investments
B39: Less pension deficit, net | C39: CHF m | E39: =-Pensions
B40: Equity value | C40: CHF m | E40: =SUM(E34:E39)
B41: Diluted shares outstanding | C41: m | E41: =Shares
B42: Value per share | C42: CHF | E42: =IF(Model_Valid=1,E40/E41,"n/a")
B43: Current share price | C43: CHF | E43: =Share_Price
B44: Upside / (downside) to current price | C44: % | E44: =IF(AND(ISNUMBER(E42),E43>0),E42/E43-1,"n/a")
B45: Terminal value as share of enterprise value | C45: % | E45: =IF(E34<>0,E33/E34,0)
...

Sheet Sensitivities
B1: Sensitivities
B2: =IF(Company_Name="","Company not specified",Company_Name)&" | CHF m unless stated otherwise | Scenario: "&IF(Build_Flag=1,Scenario,"not used (direct FCF)")&" | Checks: "&Check_Status
B4: Value per share: WACC (rows) and terminal growth (columns), perpetuity growth method
C5: WACC / g | D5: =TGR-2*Step_TGR | E5: =TGR-Step_TGR | F5: =TGR | G5: =TGR+Step_TGR | H5: =TGR+2*Step_TGR
C6: =WACC-2*Step_WACC | D6: =IF(AND(Inputs_OK=1,D$5<$C6),(SUMPRODUCT(FCF_Used,In_Forecast,1/(1+$C6)^Disc_Period)+FCF_N*(1+D$5)/($C6-D$5)/(1+$C6)^(Forecast_Years-Mid_Year)+Net_Bridge)/Shares,"n/a") | E6: =IF(AND(Inputs_OK=1,E$5<$C6),(SUMPRODUCT(FCF_Used,In_Forecast,1/(1+$C6)^Disc_Period)+FCF_N*(1+E$5)/($C6-E$5)/(1+$C6)^(Forecast_Years-Mid_Year)+Net_Bridge)/Shares,"n/a") | F6: =IF(AND(Inputs_OK=1,F$5<$C6),(SUMPRODUCT(FCF_Used,In_Forecast,1/(1+$C6)^Disc_Period)+FCF_N*(1+F$5)/($C6-F$5)/(1+$C6)^(Forecast_Years-Mid_Year)+Net_Bridge)/Shares,"n/a") | G6: =IF(AND(Inputs_OK=1,G$5<$C6),(SUMPRODUCT(FCF_Used,In_Forecast,1/(1+$C6)^Disc_Period)+FCF_N*(1+G$5)/($C6-G$5)/(1+$C6)^(Forecast_Years-Mid_Year)+Net_Bridge)/Shares,"n/a") | H6: =IF(AND(Inputs_OK=1,H$5<$C6),(SUMPRODUCT(FCF_Used,In_Forecast,1/(1+$C6)^Disc_Period)+FCF_N*(1+H$5)/($C6-H$5)/(1+$C6)^(Forecast_Years-Mid_Year)+Net_Bridge)/Shares,"n/a")
C7: =WACC-Step_WACC | D7: =IF(AND(Inputs_OK=1,D$5<$C7),(SUMPRODUCT(FCF_Used,In_Forecast,1/(1+$C7)^Disc_Period)+FCF_N*(1+D$5)/($C7-D$5)/(1+$C7)^(Forecast_Years-Mid_Year)+Net_Bridge)/Shares,"n/a") | E7: =IF(AND(Inputs_OK=1,E$5<$C7),(SUMPRODUCT(FCF_Used,In_Forecast,1/(1+$C7)^Disc_Period)+FCF_N*(1+E$5)/($C7-E$5)/(1+$C7)^(Forecast_Years-Mid_Year)+Net_Bridge)/Shares,"n/a") | F7: =IF(AND(Inputs_OK=1,F$5<$C7),(SUMPRODUCT(FCF_Used,In_Forecast,1/(1+$C7)^Disc_Period)+FCF_N*(1+F$5)/($C7-F$5)/(1+$C7)^(Forecast_Years-Mid_Year)+Net_Bridge)/Shares,"n/a") | G7: =IF(AND(Inputs_OK=1,G$5<$C7),(SUMPRODUCT(FCF_Used,In_Forecast,1/(1+$C7)^Disc_Period)+FCF_N*(1+G$5)/($C7-G$5)/(1+$C7)^(Forecast_Years-Mid_Year)+Net_Bridge)/Shares,"n/a") | H7: =IF(AND(Inputs_OK=1,H$5<$C7),(SUMPRODUCT(FCF_Used,In_Forecast,1/(1+$C7)^Disc_Period)+FCF_N*(1+H$5)/($C7-H$5)/(1+$C7)^(Forecast_Years-Mid_Year)+Net_Bridge)/Shares,"n/a")
C8: =WACC | D8: =IF(AND(Inputs_OK=1,D$5<$C8),(SUMPRODUCT(FCF_Used,In_Forecast,1/(1+$C8)^Disc_Period)+FCF_N*(1+D$5)/($C8-D$5)/(1+$C8)^(Forecast_Years-Mid_Year)+Net_Bridge)/Shares,"n/a") | E8: =IF(AND(Inputs_OK=1,E$5<$C8),(SUMPRODUCT(FCF_Used,In_Forecast,1/(1+$C8)^Disc_Period)+FCF_N*(1+E$5)/($C8-E$5)/(1+$C8)^(Forecast_Years-Mid_Year)+Net_Bridge)/Shares,"n/a") | F8: =IF(AND(Inputs_OK=1,F$5<$C8),(SUMPRODUCT(FCF_Used,In_Forecast,1/(1+$C8)^Disc_Period)+FCF_N*(1+F$5)/($C8-F$5)/(1+$C8)^(Forecast_Years-Mid_Year)+Net_Bridge)/Shares,"n/a") | G8: =IF(AND(Inputs_OK=1,G$5<$C8),(SUMPRODUCT(FCF_Used,In_Forecast,1/(1+$C8)^Disc_Period)+FCF_N*(1+G$5)/($C8-G$5)/(1+$C8)^(Forecast_Years-Mid_Year)+Net_Bridge)/Shares,"n/a") | H8: =IF(AND(Inputs_OK=1,H$5<$C8),(SUMPRODUCT(FCF_Used,In_Forecast,1/(1+$C8)^Disc_Period)+FCF_N*(1+H$5)/($C8-H$5)/(1+$C8)^(Forecast_Years-Mid_Year)+Net_Bridge)/Shares,"n/a")
C9: =WACC+Step_WACC | D9: =IF(AND(Inputs_OK=1,D$5<$C9),(SUMPRODUCT(FCF_Used,In_Forecast,1/(1+$C9)^Disc_Period)+FCF_N*(1+D$5)/($C9-D$5)/(1+$C9)^(Forecast_Years-Mid_Year)+Net_Bridge)/Shares,"n/a") | E9: =IF(AND(Inputs_OK=1,E$5<$C9),(SUMPRODUCT(FCF_Used,In_Forecast,1/(1+$C9)^Disc_Period)+FCF_N*(1+E$5)/($C9-E$5)/(1+$C9)^(Forecast_Years-Mid_Year)+Net_Bridge)/Shares,"n/a") | F9: =IF(AND(Inputs_OK=1,F$5<$C9),(SUMPRODUCT(FCF_Used,In_Forecast,1/(1+$C9)^Disc_Period)+FCF_N*(1+F$5)/($C9-F$5)/(1+$C9)^(Forecast_Years-Mid_Year)+Net_Bridge)/Shares,"n/a") | G9: =IF(AND(Inputs_OK=1,G$5<$C9),(SUMPRODUCT(FCF_Used,In_Forecast,1/(1+$C9)^Disc_Period)+FCF_N*(1+G$5)/($C9-G$5)/(1+$C9)^(Forecast_Years-Mid_Year)+Net_Bridge)/Shares,"n/a") | H9: =IF(AND(Inputs_OK=1,H$5<$C9),(SUMPRODUCT(FCF_Used,In_Forecast,1/(1+$C9)^Disc_Period)+FCF_N*(1+H$5)/($C9-H$5)/(1+$C9)^(Forecast_Years-Mid_Year)+Net_Bridge)/Shares,"n/a")
C10: =WACC+2*Step_WACC | D10: =IF(AND(Inputs_OK=1,D$5<$C10),(SUMPRODUCT(FCF_Used,In_Forecast,1/(1+$C10)^Disc_Period)+FCF_N*(1+D$5)/($C10-D$5)/(1+$C10)^(Forecast_Years-Mid_Year)+Net_Bridge)/Shares,"n/a") | E10: =IF(AND(Inputs_OK=1,E$5<$C10),(SUMPRODUCT(FCF_Used,In_Forecast,1/(1+$C10)^Disc_Period)+FCF_N*(1+E$5)/($C10-E$5)/(1+$C10)^(Forecast_Years-Mid_Year)+Net_Bridge)/Shares,"n/a") | F10: =IF(AND(Inputs_OK=1,F$5<$C10),(SUMPRODUCT(FCF_Used,In_Forecast,1/(1+$C10)^Disc_Period)+FCF_N*(1+F$5)/($C10-F$5)/(1+$C10)^(Forecast_Years-Mid_Year)+Net_Bridge)/Shares,"n/a") | G10: =IF(AND(Inputs_OK=1,G$5<$C10),(SUMPRODUCT(FCF_Used,In_Forecast,1/(1+$C10)^Disc_Period)+FCF_N*(1+G$5)/($C10-G$5)/(1+$C10)^(Forecast_Years-Mid_Year)+Net_Bridge)/Shares,"n/a") | H10: =IF(AND(Inputs_OK=1,H$5<$C10),(SUMPRODUCT(FCF_Used,In_Forecast,1/(1+$C10)^Disc_Period)+FCF_N*(1+H$5)/($C10-H$5)/(1+$C10)^(Forecast_Years-Mid_Year)+Net_Bridge)/Shares,"n/a")
B13: Value per share: WACC (rows) and exit multiple (columns), exit multiple method
C14: WACC / multiple | D14: =Exit_Multiple-2*Step_Multiple | E14: =Exit_Multiple-Step_Multiple | F14: =Exit_Multiple | G14: =Exit_Multiple+Step_Multiple | H14: =Exit_Multiple+2*Step_Multiple
C15: =WACC-2*Step_WACC | D15: =IF(AND(Inputs_OK=1,Build_Flag=1),(SUMPRODUCT(FCF_Used,In_Forecast,1/(1+$C15)^Disc_Period)+EBITDA_N*D$14/(1+$C15)^Forecast_Years+Net_Bridge)/Shares,"n/a") | E15: =IF(AND(Inputs_OK=1,Build_Flag=1),(SUMPRODUCT(FCF_Used,In_Forecast,1/(1+$C15)^Disc_Period)+EBITDA_N*E$14/(1+$C15)^Forecast_Years+Net_Bridge)/Shares,"n/a") | F15: =IF(AND(Inputs_OK=1,Build_Flag=1),(SUMPRODUCT(FCF_Used,In_Forecast,1/(1+$C15)^Disc_Period)+EBITDA_N*F$14/(1+$C15)^Forecast_Years+Net_Bridge)/Shares,"n/a") | G15: =IF(AND(Inputs_OK=1,Build_Flag=1),(SUMPRODUCT(FCF_Used,In_Forecast,1/(1+$C15)^Disc_Period)+EBITDA_N*G$14/(1+$C15)^Forecast_Years+Net_Bridge)/Shares,"n/a") | H15: =IF(AND(Inputs_OK=1,Build_Flag=1),(SUMPRODUCT(FCF_Used,In_Forecast,1/(1+$C15)^Disc_Period)+EBITDA_N*H$14/(1+$C15)^Forecast_Years+Net_Bridge)/Shares,"n/a")
C16: =WACC-Step_WACC | D16: =IF(AND(Inputs_OK=1,Build_Flag=1),(SUMPRODUCT(FCF_Used,In_Forecast,1/(1+$C16)^Disc_Period)+EBITDA_N*D$14/(1+$C16)^Forecast_Years+Net_Bridge)/Shares,"n/a") | E16: =IF(AND(Inputs_OK=1,Build_Flag=1),(SUMPRODUCT(FCF_Used,In_Forecast,1/(1+$C16)^Disc_Period)+EBITDA_N*E$14/(1+$C16)^Forecast_Years+Net_Bridge)/Shares,"n/a") | F16: =IF(AND(Inputs_OK=1,Build_Flag=1),(SUMPRODUCT(FCF_Used,In_Forecast,1/(1+$C16)^Disc_Period)+EBITDA_N*F$14/(1+$C16)^Forecast_Years+Net_Bridge)/Shares,"n/a") | G16: =IF(AND(Inputs_OK=1,Build_Flag=1),(SUMPRODUCT(FCF_Used,In_Forecast,1/(1+$C16)^Disc_Period)+EBITDA_N*G$14/(1+$C16)^Forecast_Years+Net_Bridge)/Shares,"n/a") | H16: =IF(AND(Inputs_OK=1,Build_Flag=1),(SUMPRODUCT(FCF_Used,In_Forecast,1/(1+$C16)^Disc_Period)+EBITDA_N*H$14/(1+$C16)^Forecast_Years+Net_Bridge)/Shares,"n/a")
C17: =WACC | D17: =IF(AND(Inputs_OK=1,Build_Flag=1),(SUMPRODUCT(FCF_Used,In_Forecast,1/(1+$C17)^Disc_Period)+EBITDA_N*D$14/(1+$C17)^Forecast_Years+Net_Bridge)/Shares,"n/a") | E17: =IF(AND(Inputs_OK=1,Build_Flag=1),(SUMPRODUCT(FCF_Used,In_Forecast,1/(1+$C17)^Disc_Period)+EBITDA_N*E$14/(1+$C17)^Forecast_Years+Net_Bridge)/Shares,"n/a") | F17: =IF(AND(Inputs_OK=1,Build_Flag=1),(SUMPRODUCT(FCF_Used,In_Forecast,1/(1+$C17)^Disc_Period)+EBITDA_N*F$14/(1+$C17)^Forecast_Years+Net_Bridge)/Shares,"n/a") | G17: =IF(AND(Inputs_OK=1,Build_Flag=1),(SUMPRODUCT(FCF_Used,In_Forecast,1/(1+$C17)^Disc_Period)+EBITDA_N*G$14/(1+$C17)^Forecast_Years+Net_Bridge)/Shares,"n/a") | H17: =IF(AND(Inputs_OK=1,Build_Flag=1),(SUMPRODUCT(FCF_Used,In_Forecast,1/(1+$C17)^Disc_Period)+EBITDA_N*H$14/(1+$C17)^Forecast_Years+Net_Bridge)/Shares,"n/a")
C18: =WACC+Step_WACC | D18: =IF(AND(Inputs_OK=1,Build_Flag=1),(SUMPRODUCT(FCF_Used,In_Forecast,1/(1+$C18)^Disc_Period)+EBITDA_N*D$14/(1+$C18)^Forecast_Years+Net_Bridge)/Shares,"n/a") | E18: =IF(AND(Inputs_OK=1,Build_Flag=1),(SUMPRODUCT(FCF_Used,In_Forecast,1/(1+$C18)^Disc_Period)+EBITDA_N*E$14/(1+$C18)^Forecast_Years+Net_Bridge)/Shares,"n/a") | F18: =IF(AND(Inputs_OK=1,Build_Flag=1),(SUMPRODUCT(FCF_Used,In_Forecast,1/(1+$C18)^Disc_Period)+EBITDA_N*F$14/(1+$C18)^Forecast_Years+Net_Bridge)/Shares,"n/a") | G18: =IF(AND(Inputs_OK=1,Build_Flag=1),(SUMPRODUCT(FCF_Used,In_Forecast,1/(1+$C18)^Disc_Period)+EBITDA_N*G$14/(1+$C18)^Forecast_Years+Net_Bridge)/Shares,"n/a") | H18: =IF(AND(Inputs_OK=1,Build_Flag=1),(SUMPRODUCT(FCF_Used,In_Forecast,1/(1+$C18)^Disc_Period)+EBITDA_N*H$14/(1+$C18)^Forecast_Years+Net_Bridge)/Shares,"n/a")
C19: =WACC+2*Step_WACC | D19: =IF(AND(Inputs_OK=1,Build_Flag=1),(SUMPRODUCT(FCF_Used,In_Forecast,1/(1+$C19)^Disc_Period)+EBITDA_N*D$14/(1+$C19)^Forecast_Years+Net_Bridge)/Shares,"n/a") | E19: =IF(AND(Inputs_OK=1,Build_Flag=1),(SUMPRODUCT(FCF_Used,In_Forecast,1/(1+$C19)^Disc_Period)+EBITDA_N*E$14/(1+$C19)^Forecast_Years+Net_Bridge)/Shares,"n/a") | F19: =IF(AND(Inputs_OK=1,Build_Flag=1),(SUMPRODUCT(FCF_Used,In_Forecast,1/(1+$C19)^Disc_Period)+EBITDA_N*F$14/(1+$C19)^Forecast_Years+Net_Bridge)/Shares,"n/a") | G19: =IF(AND(Inputs_OK=1,Build_Flag=1),(SUMPRODUCT(FCF_Used,In_Forecast,1/(1+$C19)^Disc_Period)+EBITDA_N*G$14/(1+$C19)^Forecast_Years+Net_Bridge)/Shares,"n/a") | H19: =IF(AND(Inputs_OK=1,Build_Flag=1),(SUMPRODUCT(FCF_Used,In_Forecast,1/(1+$C19)^Disc_Period)+EBITDA_N*H$14/(1+$C19)^Forecast_Years+Net_Bridge)/Shares,"n/a")
B22: Upside / (downside) to current share price: WACC and terminal growth
C23: WACC / g | D23: =TGR-2*Step_TGR | E23: =TGR-Step_TGR | F23: =TGR | G23: =TGR+Step_TGR | H23: =TGR+2*Step_TGR
C24: =WACC-2*Step_WACC | D24: =IF(AND(ISNUMBER(D6),Share_Price>0),D6/Share_Price-1,"n/a") | E24: =IF(AND(ISNUMBER(E6),Share_Price>0),E6/Share_Price-1,"n/a") | F24: =IF(AND(ISNUMBER(F6),Share_Price>0),F6/Share_Price-1,"n/a") | G24: =IF(AND(ISNUMBER(G6),Share_Price>0),G6/Share_Price-1,"n/a") | H24: =IF(AND(ISNUMBER(H6),Share_Price>0),H6/Share_Price-1,"n/a")
C25: =WACC-Step_WACC | D25: =IF(AND(ISNUMBER(D7),Share_Price>0),D7/Share_Price-1,"n/a") | E25: =IF(AND(ISNUMBER(E7),Share_Price>0),E7/Share_Price-1,"n/a") | F25: =IF(AND(ISNUMBER(F7),Share_Price>0),F7/Share_Price-1,"n/a") | G25: =IF(AND(ISNUMBER(G7),Share_Price>0),G7/Share_Price-1,"n/a") | H25: =IF(AND(ISNUMBER(H7),Share_Price>0),H7/Share_Price-1,"n/a")
C26: =WACC | D26: =IF(AND(ISNUMBER(D8),Share_Price>0),D8/Share_Price-1,"n/a") | E26: =IF(AND(ISNUMBER(E8),Share_Price>0),E8/Share_Price-1,"n/a") | F26: =IF(AND(ISNUMBER(F8),Share_Price>0),F8/Share_Price-1,"n/a") | G26: =IF(AND(ISNUMBER(G8),Share_Price>0),G8/Share_Price-1,"n/a") | H26: =IF(AND(ISNUMBER(H8),Share_Price>0),H8/Share_Price-1,"n/a")
C27: =WACC+Step_WACC | D27: =IF(AND(ISNUMBER(D9),Share_Price>0),D9/Share_Price-1,"n/a") | E27: =IF(AND(ISNUMBER(E9),Share_Price>0),E9/Share_Price-1,"n/a") | F27: =IF(AND(ISNUMBER(F9),Share_Price>0),F9/Share_Price-1,"n/a") | G27: =IF(AND(ISNUMBER(G9),Share_Price>0),G9/Share_Price-1,"n/a") | H27: =IF(AND(ISNUMBER(H9),Share_Price>0),H9/Share_Price-1,"n/a")
C28: =WACC+2*Step_WACC | D28: =IF(AND(ISNUMBER(D10),Share_Price>0),D10/Share_Price-1,"n/a") | E28: =IF(AND(ISNUMBER(E10),Share_Price>0),E10/Share_Price-1,"n/a") | F28: =IF(AND(ISNUMBER(F10),Share_Price>0),F10/Share_Price-1,"n/a") | G28: =IF(AND(ISNUMBER(G10),Share_Price>0),G10/Share_Price-1,"n/a") | H28: =IF(AND(ISNUMBER(H10),Share_Price>0),H10/Share_Price-1,"n/a")
B31: Light blue: at or above the current share price. Light amber: below. Centre cell: DCF result.

Sheet Reverse DCF
B1: Reverse DCF
B2: =IF(Company_Name="","Company not specified",Company_Name)&" | CHF m unless stated otherwise | Scenario: "&IF(Build_Flag=1,Scenario,"not used (direct FCF)")&" | Checks: "&Check_Status
B6: Result
B8: =IF(Build_Flag=1,"Implied revenue growth, years 1 to 5","Implied FCF growth, years 1 to 5") | E8: % | F8: =IF(AND(Model_Valid=1,OR(Build_Flag=1,Base_FCF>0),Share_Price>=F82,Share_Price<=F83),E80,"n/a") | I8: ='FCF Build'!E4 | J8: ='FCF Build'!F4 | K8: ='FCF Build'!G4 | L8: ='FCF Build'!H4 | M8: ='FCF Build'!I4 | N8: ='FCF Build'!J4 | O8: ='FCF Build'!K4 | P8: ='FCF Build'!L4 | ... S8: ='FCF Build'!O4
B9: Value per share at implied growth | E9: CHF | F9: =IF(ISNUMBER(F8),F84,"n/a") | J9: =DCF!F6 | K9: =DCF!G6 | L9: =DCF!H6 | M9: =DCF!I6 | N9: =DCF!J6 | O9: =DCF!K6 | P9: =DCF!L6 | Q9: =DCF!M6 | ... S9: =DCF!O6
B10: Difference to share price | E10: CHF | F10: =IF(ISNUMBER(F8),F9-Share_Price,"n/a") | J10: =DCF!F11 | K10: =DCF!G11 | L10: =DCF!H11 | M10: =DCF!I11 | N10: =DCF!J11 | O10: =DCF!K11 | P10: =DCF!L11 | Q10: =DCF!M11 | ... S10: =DCF!O11
B11: Status | F11: =IF(Model_Valid=0,"Not available: check inputs",IF(AND(Build_Flag=0,Base_FCF<=0),"No solution: FCF zero or negative",IF(Share_Price<F82,"No solution: price below value at lowest growth",IF(Share_Price>F83,"No solution: price above value at highest growth","Solved")))) | J11: ='FCF Build'!F11*(1-Tax_Rate)+DA_Pct-Capex_Pct | K11: ='FCF Build'!G11*(1-Tax_Rate)+DA_Pct-Capex_Pct | L11: ='FCF Build'!H11*(1-Tax_Rate)+DA_Pct-Capex_Pct | M11: ='FCF Build'!I11*(1-Tax_Rate)+DA_Pct-Capex_Pct | N11: ='FCF Build'!J11*(1-Tax_Rate)+DA_Pct-Capex_Pct | O11: ='FCF Build'!K11*(1-Tax_Rate)+DA_Pct-Capex_Pct | P11: ='FCF Build'!L11*(1-Tax_Rate)+DA_Pct-Capex_Pct | Q11: ='FCF Build'!M11*(1-Tax_Rate)+DA_Pct-Capex_Pct | ... S11: ='FCF Build'!O11*(1-Tax_Rate)+DA_Pct-Capex_Pct
B12: =IF(ISNUMBER(F8),"The current share price of CHF "&FIXED(Share_Price,2)&" implies "&IF(Build_Flag=1,"revenue","free cash flow")&" growth of "&FIXED(F8*100,1)&"% per year in years 1 to 5.","") | J12: ='FCF Build'!F11+DA_Pct | K12: ='FCF Build'!G11+DA_Pct | L12: ='FCF Build'!H11+DA_Pct | M12: ='FCF Build'!I11+DA_Pct | N12: ='FCF Build'!J11+DA_Pct | O12: ='FCF Build'!K11+DA_Pct | P12: ='FCF Build'!L11+DA_Pct | Q12: ='FCF Build'!M11+DA_Pct | ... S12: ='FCF Build'!O11+DA_Pct
B14: Implied WACC (growth unchanged) | E14: % | F14: =IF(AND(Inputs_OK=1,OR(Exit_Flag=0,Build_Flag=1),C88<D88,Share_Price<=F150,Share_Price>=F151),E148,"n/a")
B15: Difference to share price | E15: CHF | F15: =IF(ISNUMBER(F14),F152-Share_Price,"n/a")
B16: Status | F16: =IF(OR(Inputs_OK=0,AND(Exit_Flag=1,Build_Flag=0)),"Not available: check inputs",IF(C88>=D88,"No solution: terminal growth too high",IF(Share_Price>F150,"No solution: price above value at lowest WACC",IF(Share_Price<F151,"No solution: price below value at highest WACC","Solved"))))
B18: Growth search: bisection
B19: Iteration | C19: Lower | D19: Upper | E19: Midpoint | F19: Value per share at midpoint | G19: Value less price | I19: Growth factor Y0 | J19: Growth factor Y1 | K19: Growth factor Y2 | L19: Growth factor Y3 | M19: Growth factor Y4 | N19: Growth factor Y5 | O19: Growth factor Y6 | P19: Growth factor Y7 | Q19: Growth factor Y8 | R19: Growth factor Y9 | S19: Growth factor Y10 | T19: Factor year N | U19: Factor year N-1 | V19: FCF in year N | W19: PV of FCFs | X19: PV of terminal value
B20: =1 | C20: =Growth_Lower | D20: =Growth_Upper | E20: =(C20+D20)/2 | F20: =IF(Inputs_OK=1,(W20+X20+Net_Bridge)/Shares,0) | G20: =F20-Share_Price | I20: =1 | J20: =I20*(1+IF(J$8<=5,$E20,$E20+(TGR-$E20)*(J$8-5)/5)) | K20: =J20*(1+IF(K$8<=5,$E20,$E20+(TGR-$E20)*(K$8-5)/5)) | L20: =K20*(1+IF(L$8<=5,$E20,$E20+(TGR-$E20)*(L$8-5)/5)) | M20: =L20*(1+IF(M$8<=5,$E20,$E20+(TGR-$E20)*(M$8-5)/5)) | N20: =M20*(1+IF(N$8<=5,$E20,$E20+(TGR-$E20)*(N$8-5)/5)) | O20: =N20*(1+IF(O$8<=5,$E20,$E20+(TGR-$E20)*(O$8-5)/5)) | P20: =O20*(1+IF(P$8<=5,$E20,$E20+(TGR-$E20)*(P$8-5)/5)) | Q20: =P20*(1+IF(Q$8<=5,$E20,$E20+(TGR-$E20)*(Q$8-5)/5)) | ... S20: =R20*(1+IF(S$8<=5,$E20,$E20+(TGR-$E20)*(S$8-5)/5)) | T20: =INDEX($J20:$S20,1,Forecast_Years) | U20: =INDEX($I20:$S20,1,Forecast_Years) | V20: =Build_Flag*Base_Revenue*(T20*INDEX($J$11:$S$11,1,Forecast_Years)-NWC_Pct*(T20-U20))+(1-Build_Flag)*Base_FCF*T20 | W20: =SUMPRODUCT($J$9:$S$9,$J$10:$S$10,Build_Flag*Base_Revenue*($J20:$S20*$J$11:$S$11-NWC_Pct*($J20:$S20-$I20:$R20))+(1-Build_Flag)*Base_FCF*$J20:$S20) | X20: =IF(Exit_Flag=1,Base_Revenue*T20*INDEX($J$12:$S$12,1,Forecast_Years)*Exit_Multiple/(1+WACC)^Forecast_Years,IF(TGR<WACC,V20*(1+TGR)/(WACC-TGR)/(1+WACC)^(Forecast_Years-Mid_Year),0))
B21: =B20+1 | C21: =IF(F20<Share_Price,E20,C20) | D21: =IF(F20<Share_Price,D20,E20) | E21: =(C21+D21)/2 | F21: =IF(Inputs_OK=1,(W21+X21+Net_Bridge)/Shares,0) | G21: =F21-Share_Price | I21: =1 | J21: =I21*(1+IF(J$8<=5,$E21,$E21+(TGR-$E21)*(J$8-5)/5)) | K21: =J21*(1+IF(K$8<=5,$E21,$E21+(TGR-$E21)*(K$8-5)/5)) | L21: =K21*(1+IF(L$8<=5,$E21,$E21+(TGR-$E21)*(L$8-5)/5)) | M21: =L21*(1+IF(M$8<=5,$E21,$E21+(TGR-$E21)*(M$8-5)/5)) | N21: =M21*(1+IF(N$8<=5,$E21,$E21+(TGR-$E21)*(N$8-5)/5)) | O21: =N21*(1+IF(O$8<=5,$E21,$E21+(TGR-$E21)*(O$8-5)/5)) | P21: =O21*(1+IF(P$8<=5,$E21,$E21+(TGR-$E21)*(P$8-5)/5)) | Q21: =P21*(1+IF(Q$8<=5,$E21,$E21+(TGR-$E21)*(Q$8-5)/5)) | ... S21: =R21*(1+IF(S$8<=5,$E21,$E21+(TGR-$E21)*(S$8-5)/5)) | T21: =INDEX($J21:$S21,1,Forecast_Years) | U21: =INDEX($I21:$S21,1,Forecast_Years) | V21: =Build_Flag*Base_Revenue*(T21*INDEX($J$11:$S$11,1,Forecast_Years)-NWC_Pct*(T21-U21))+(1-Build_Flag)*Base_FCF*T21 | W21: =SUMPRODUCT($J$9:$S$9,$J$10:$S$10,Build_Flag*Base_Revenue*($J21:$S21*$J$11:$S$11-NWC_Pct*($J21:$S21-$I21:$R21))+(1-Build_Flag)*Base_FCF*$J21:$S21) | X21: =IF(Exit_Flag=1,Base_Revenue*T21*INDEX($J$12:$S$12,1,Forecast_Years)*Exit_Multiple/(1+WACC)^Forecast_Years,IF(TGR<WACC,V21*(1+TGR)/(WACC-TGR)/(1+WACC)^(Forecast_Years-Mid_Year),0))
B22: =B21+1 | C22: =IF(F21<Share_Price,E21,C21) | D22: =IF(F21<Share_Price,D21,E21) | E22: =(C22+D22)/2 | F22: =IF(Inputs_OK=1,(W22+X22+Net_Bridge)/Shares,0) | G22: =F22-Share_Price | I22: =1 | J22: =I22*(1+IF(J$8<=5,$E22,$E22+(TGR-$E22)*(J$8-5)/5)) | K22: =J22*(1+IF(K$8<=5,$E22,$E22+(TGR-$E22)*(K$8-5)/5)) | L22: =K22*(1+IF(L$8<=5,$E22,$E22+(TGR-$E22)*(L$8-5)/5)) | M22: =L22*(1+IF(M$8<=5,$E22,$E22+(TGR-$E22)*(M$8-5)/5)) | N22: =M22*(1+IF(N$8<=5,$E22,$E22+(TGR-$E22)*(N$8-5)/5)) | O22: =N22*(1+IF(O$8<=5,$E22,$E22+(TGR-$E22)*(O$8-5)/5)) | P22: =O22*(1+IF(P$8<=5,$E22,$E22+(TGR-$E22)*(P$8-5)/5)) | Q22: =P22*(1+IF(Q$8<=5,$E22,$E22+(TGR-$E22)*(Q$8-5)/5)) | ... S22: =R22*(1+IF(S$8<=5,$E22,$E22+(TGR-$E22)*(S$8-5)/5)) | T22: =INDEX($J22:$S22,1,Forecast_Years) | U22: =INDEX($I22:$S22,1,Forecast_Years) | V22: =Build_Flag*Base_Revenue*(T22*INDEX($J$11:$S$11,1,Forecast_Years)-NWC_Pct*(T22-U22))+(1-Build_Flag)*Base_FCF*T22 | W22: =SUMPRODUCT($J$9:$S$9,$J$10:$S$10,Build_Flag*Base_Revenue*($J22:$S22*$J$11:$S$11-NWC_Pct*($J22:$S22-$I22:$R22))+(1-Build_Flag)*Base_FCF*$J22:$S22) | X22: =IF(Exit_Flag=1,Base_Revenue*T22*INDEX($J$12:$S$12,1,Forecast_Years)*Exit_Multiple/(1+WACC)^Forecast_Years,IF(TGR<WACC,V22*(1+TGR)/(WACC-TGR)/(1+WACC)^(Forecast_Years-Mid_Year),0))
B23: =B22+1 | C23: =IF(F22<Share_Price,E22,C22) | D23: =IF(F22<Share_Price,D22,E22) | E23: =(C23+D23)/2 | F23: =IF(Inputs_OK=1,(W23+X23+Net_Bridge)/Shares,0) | G23: =F23-Share_Price | I23: =1 | J23: =I23*(1+IF(J$8<=5,$E23,$E23+(TGR-$E23)*(J$8-5)/5)) | K23: =J23*(1+IF(K$8<=5,$E23,$E23+(TGR-$E23)*(K$8-5)/5)) | L23: =K23*(1+IF(L$8<=5,$E23,$E23+(TGR-$E23)*(L$8-5)/5)) | M23: =L23*(1+IF(M$8<=5,$E23,$E23+(TGR-$E23)*(M$8-5)/5)) | N23: =M23*(1+IF(N$8<=5,$E23,$E23+(TGR-$E23)*(N$8-5)/5)) | O23: =N23*(1+IF(O$8<=5,$E23,$E23+(TGR-$E23)*(O$8-5)/5)) | P23: =O23*(1+IF(P$8<=5,$E23,$E23+(TGR-$E23)*(P$8-5)/5)) | Q23: =P23*(1+IF(Q$8<=5,$E23,$E23+(TGR-$E23)*(Q$8-5)/5)) | ... S23: =R23*(1+IF(S$8<=5,$E23,$E23+(TGR-$E23)*(S$8-5)/5)) | T23: =INDEX($J23:$S23,1,Forecast_Years) | U23: =INDEX($I23:$S23,1,Forecast_Years) | V23: =Build_Flag*Base_Revenue*(T23*INDEX($J$11:$S$11,1,Forecast_Years)-NWC_Pct*(T23-U23))+(1-Build_Flag)*Base_FCF*T23 | W23: =SUMPRODUCT($J$9:$S$9,$J$10:$S$10,Build_Flag*Base_Revenue*($J23:$S23*$J$11:$S$11-NWC_Pct*($J23:$S23-$I23:$R23))+(1-Build_Flag)*Base_FCF*$J23:$S23) | X23: =IF(Exit_Flag=1,Base_Revenue*T23*INDEX($J$12:$S$12,1,Forecast_Years)*Exit_Multiple/(1+WACC)^Forecast_Years,IF(TGR<WACC,V23*(1+TGR)/(WACC-TGR)/(1+WACC)^(Forecast_Years-Mid_Year),0))
B24: =B23+1 | C24: =IF(F23<Share_Price,E23,C23) | D24: =IF(F23<Share_Price,D23,E23) | E24: =(C24+D24)/2 | F24: =IF(Inputs_OK=1,(W24+X24+Net_Bridge)/Shares,0) | G24: =F24-Share_Price | I24: =1 | J24: =I24*(1+IF(J$8<=5,$E24,$E24+(TGR-$E24)*(J$8-5)/5)) | K24: =J24*(1+IF(K$8<=5,$E24,$E24+(TGR-$E24)*(K$8-5)/5)) | L24: =K24*(1+IF(L$8<=5,$E24,$E24+(TGR-$E24)*(L$8-5)/5)) | M24: =L24*(1+IF(M$8<=5,$E24,$E24+(TGR-$E24)*(M$8-5)/5)) | N24: =M24*(1+IF(N$8<=5,$E24,$E24+(TGR-$E24)*(N$8-5)/5)) | O24: =N24*(1+IF(O$8<=5,$E24,$E24+(TGR-$E24)*(O$8-5)/5)) | P24: =O24*(1+IF(P$8<=5,$E24,$E24+(TGR-$E24)*(P$8-5)/5)) | Q24: =P24*(1+IF(Q$8<=5,$E24,$E24+(TGR-$E24)*(Q$8-5)/5)) | ... S24: =R24*(1+IF(S$8<=5,$E24,$E24+(TGR-$E24)*(S$8-5)/5)) | T24: =INDEX($J24:$S24,1,Forecast_Years) | U24: =INDEX($I24:$S24,1,Forecast_Years) | V24: =Build_Flag*Base_Revenue*(T24*INDEX($J$11:$S$11,1,Forecast_Years)-NWC_Pct*(T24-U24))+(1-Build_Flag)*Base_FCF*T24 | W24: =SUMPRODUCT($J$9:$S$9,$J$10:$S$10,Build_Flag*Base_Revenue*($J24:$S24*$J$11:$S$11-NWC_Pct*($J24:$S24-$I24:$R24))+(1-Build_Flag)*Base_FCF*$J24:$S24) | X24: =IF(Exit_Flag=1,Base_Revenue*T24*INDEX($J$12:$S$12,1,Forecast_Years)*Exit_Multiple/(1+WACC)^Forecast_Years,IF(TGR<WACC,V24*(1+TGR)/(WACC-TGR)/(1+WACC)^(Forecast_Years-Mid_Year),0))
B25: =B24+1 | C25: =IF(F24<Share_Price,E24,C24) | D25: =IF(F24<Share_Price,D24,E24) | E25: =(C25+D25)/2 | F25: =IF(Inputs_OK=1,(W25+X25+Net_Bridge)/Shares,0) | G25: =F25-Share_Price | I25: =1 | J25: =I25*(1+IF(J$8<=5,$E25,$E25+(TGR-$E25)*(J$8-5)/5)) | K25: =J25*(1+IF(K$8<=5,$E25,$E25+(TGR-$E25)*(K$8-5)/5)) | L25: =K25*(1+IF(L$8<=5,$E25,$E25+(TGR-$E25)*(L$8-5)/5)) | M25: =L25*(1+IF(M$8<=5,$E25,$E25+(TGR-$E25)*(M$8-5)/5)) | N25: =M25*(1+IF(N$8<=5,$E25,$E25+(TGR-$E25)*(N$8-5)/5)) | O25: =N25*(1+IF(O$8<=5,$E25,$E25+(TGR-$E25)*(O$8-5)/5)) | P25: =O25*(1+IF(P$8<=5,$E25,$E25+(TGR-$E25)*(P$8-5)/5)) | Q25: =P25*(1+IF(Q$8<=5,$E25,$E25+(TGR-$E25)*(Q$8-5)/5)) | ... S25: =R25*(1+IF(S$8<=5,$E25,$E25+(TGR-$E25)*(S$8-5)/5)) | T25: =INDEX($J25:$S25,1,Forecast_Years) | U25: =INDEX($I25:$S25,1,Forecast_Years) | V25: =Build_Flag*Base_Revenue*(T25*INDEX($J$11:$S$11,1,Forecast_Years)-NWC_Pct*(T25-U25))+(1-Build_Flag)*Base_FCF*T25 | W25: =SUMPRODUCT($J$9:$S$9,$J$10:$S$10,Build_Flag*Base_Revenue*($J25:$S25*$J$11:$S$11-NWC_Pct*($J25:$S25-$I25:$R25))+(1-Build_Flag)*Base_FCF*$J25:$S25) | X25: =IF(Exit_Flag=1,Base_Revenue*T25*INDEX($J$12:$S$12,1,Forecast_Years)*Exit_Multiple/(1+WACC)^Forecast_Years,IF(TGR<WACC,V25*(1+TGR)/(WACC-TGR)/(1+WACC)^(Forecast_Years-Mid_Year),0))
B26: =B25+1 | C26: =IF(F25<Share_Price,E25,C25) | D26: =IF(F25<Share_Price,D25,E25) | E26: =(C26+D26)/2 | F26: =IF(Inputs_OK=1,(W26+X26+Net_Bridge)/Shares,0) | G26: =F26-Share_Price | I26: =1 | J26: =I26*(1+IF(J$8<=5,$E26,$E26+(TGR-$E26)*(J$8-5)/5)) | K26: =J26*(1+IF(K$8<=5,$E26,$E26+(TGR-$E26)*(K$8-5)/5)) | L26: =K26*(1+IF(L$8<=5,$E26,$E26+(TGR-$E26)*(L$8-5)/5)) | M26: =L26*(1+IF(M$8<=5,$E26,$E26+(TGR-$E26)*(M$8-5)/5)) | N26: =M26*(1+IF(N$8<=5,$E26,$E26+(TGR-$E26)*(N$8-5)/5)) | O26: =N26*(1+IF(O$8<=5,$E26,$E26+(TGR-$E26)*(O$8-5)/5)) | P26: =O26*(1+IF(P$8<=5,$E26,$E26+(TGR-$E26)*(P$8-5)/5)) | Q26: =P26*(1+IF(Q$8<=5,$E26,$E26+(TGR-$E26)*(Q$8-5)/5)) | ... S26: =R26*(1+IF(S$8<=5,$E26,$E26+(TGR-$E26)*(S$8-5)/5)) | T26: =INDEX($J26:$S26,1,Forecast_Years) | U26: =INDEX($I26:$S26,1,Forecast_Years) | V26: =Build_Flag*Base_Revenue*(T26*INDEX($J$11:$S$11,1,Forecast_Years)-NWC_Pct*(T26-U26))+(1-Build_Flag)*Base_FCF*T26 | W26: =SUMPRODUCT($J$9:$S$9,$J$10:$S$10,Build_Flag*Base_Revenue*($J26:$S26*$J$11:$S$11-NWC_Pct*($J26:$S26-$I26:$R26))+(1-Build_Flag)*Base_FCF*$J26:$S26) | X26: =IF(Exit_Flag=1,Base_Revenue*T26*INDEX($J$12:$S$12,1,Forecast_Years)*Exit_Multiple/(1+WACC)^Forecast_Years,IF(TGR<WACC,V26*(1+TGR)/(WACC-TGR)/(1+WACC)^(Forecast_Years-Mid_Year),0))
B27: =B26+1 | C27: =IF(F26<Share_Price,E26,C26) | D27: =IF(F26<Share_Price,D26,E26) | E27: =(C27+D27)/2 | F27: =IF(Inputs_OK=1,(W27+X27+Net_Bridge)/Shares,0) | G27: =F27-Share_Price | I27: =1 | J27: =I27*(1+IF(J$8<=5,$E27,$E27+(TGR-$E27)*(J$8-5)/5)) | K27: =J27*(1+IF(K$8<=5,$E27,$E27+(TGR-$E27)*(K$8-5)/5)) | L27: =K27*(1+IF(L$8<=5,$E27,$E27+(TGR-$E27)*(L$8-5)/5)) | M27: =L27*(1+IF(M$8<=5,$E27,$E27+(TGR-$E27)*(M$8-5)/5)) | N27: =M27*(1+IF(N$8<=5,$E27,$E27+(TGR-$E27)*(N$8-5)/5)) | O27: =N27*(1+IF(O$8<=5,$E27,$E27+(TGR-$E27)*(O$8-5)/5)) | P27: =O27*(1+IF(P$8<=5,$E27,$E27+(TGR-$E27)*(P$8-5)/5)) | Q27: =P27*(1+IF(Q$8<=5,$E27,$E27+(TGR-$E27)*(Q$8-5)/5)) | ... S27: =R27*(1+IF(S$8<=5,$E27,$E27+(TGR-$E27)*(S$8-5)/5)) | T27: =INDEX($J27:$S27,1,Forecast_Years) | U27: =INDEX($I27:$S27,1,Forecast_Years) | V27: =Build_Flag*Base_Revenue*(T27*INDEX($J$11:$S$11,1,Forecast_Years)-NWC_Pct*(T27-U27))+(1-Build_Flag)*Base_FCF*T27 | W27: =SUMPRODUCT($J$9:$S$9,$J$10:$S$10,Build_Flag*Base_Revenue*($J27:$S27*$J$11:$S$11-NWC_Pct*($J27:$S27-$I27:$R27))+(1-Build_Flag)*Base_FCF*$J27:$S27) | X27: =IF(Exit_Flag=1,Base_Revenue*T27*INDEX($J$12:$S$12,1,Forecast_Years)*Exit_Multiple/(1+WACC)^Forecast_Years,IF(TGR<WACC,V27*(1+TGR)/(WACC-TGR)/(1+WACC)^(Forecast_Years-Mid_Year),0))
B28: =B27+1 | C28: =IF(F27<Share_Price,E27,C27) | D28: =IF(F27<Share_Price,D27,E27) | E28: =(C28+D28)/2 | F28: =IF(Inputs_OK=1,(W28+X28+Net_Bridge)/Shares,0) | G28: =F28-Share_Price | I28: =1 | J28: =I28*(1+IF(J$8<=5,$E28,$E28+(TGR-$E28)*(J$8-5)/5)) | K28: =J28*(1+IF(K$8<=5,$E28,$E28+(TGR-$E28)*(K$8-5)/5)) | L28: =K28*(1+IF(L$8<=5,$E28,$E28+(TGR-$E28)*(L$8-5)/5)) | M28: =L28*(1+IF(M$8<=5,$E28,$E28+(TGR-$E28)*(M$8-5)/5)) | N28: =M28*(1+IF(N$8<=5,$E28,$E28+(TGR-$E28)*(N$8-5)/5)) | O28: =N28*(1+IF(O$8<=5,$E28,$E28+(TGR-$E28)*(O$8-5)/5)) | P28: =O28*(1+IF(P$8<=5,$E28,$E28+(TGR-$E28)*(P$8-5)/5)) | Q28: =P28*(1+IF(Q$8<=5,$E28,$E28+(TGR-$E28)*(Q$8-5)/5)) | ... S28: =R28*(1+IF(S$8<=5,$E28,$E28+(TGR-$E28)*(S$8-5)/5)) | T28: =INDEX($J28:$S28,1,Forecast_Years) | U28: =INDEX($I28:$S28,1,Forecast_Years) | V28: =Build_Flag*Base_Revenue*(T28*INDEX($J$11:$S$11,1,Forecast_Years)-NWC_Pct*(T28-U28))+(1-Build_Flag)*Base_FCF*T28 | W28: =SUMPRODUCT($J$9:$S$9,$J$10:$S$10,Build_Flag*Base_Revenue*($J28:$S28*$J$11:$S$11-NWC_Pct*($J28:$S28-$I28:$R28))+(1-Build_Flag)*Base_FCF*$J28:$S28) | X28: =IF(Exit_Flag=1,Base_Revenue*T28*INDEX($J$12:$S$12,1,Forecast_Years)*Exit_Multiple/(1+WACC)^Forecast_Years,IF(TGR<WACC,V28*(1+TGR)/(WACC-TGR)/(1+WACC)^(Forecast_Years-Mid_Year),0))
B29: =B28+1 | C29: =IF(F28<Share_Price,E28,C28) | D29: =IF(F28<Share_Price,D28,E28) | E29: =(C29+D29)/2 | F29: =IF(Inputs_OK=1,(W29+X29+Net_Bridge)/Shares,0) | G29: =F29-Share_Price | I29: =1 | J29: =I29*(1+IF(J$8<=5,$E29,$E29+(TGR-$E29)*(J$8-5)/5)) | K29: =J29*(1+IF(K$8<=5,$E29,$E29+(TGR-$E29)*(K$8-5)/5)) | L29: =K29*(1+IF(L$8<=5,$E29,$E29+(TGR-$E29)*(L$8-5)/5)) | M29: =L29*(1+IF(M$8<=5,$E29,$E29+(TGR-$E29)*(M$8-5)/5)) | N29: =M29*(1+IF(N$8<=5,$E29,$E29+(TGR-$E29)*(N$8-5)/5)) | O29: =N29*(1+IF(O$8<=5,$E29,$E29+(TGR-$E29)*(O$8-5)/5)) | P29: =O29*(1+IF(P$8<=5,$E29,$E29+(TGR-$E29)*(P$8-5)/5)) | Q29: =P29*(1+IF(Q$8<=5,$E29,$E29+(TGR-$E29)*(Q$8-5)/5)) | ... S29: =R29*(1+IF(S$8<=5,$E29,$E29+(TGR-$E29)*(S$8-5)/5)) | T29: =INDEX($J29:$S29,1,Forecast_Years) | U29: =INDEX($I29:$S29,1,Forecast_Years) | V29: =Build_Flag*Base_Revenue*(T29*INDEX($J$11:$S$11,1,Forecast_Years)-NWC_Pct*(T29-U29))+(1-Build_Flag)*Base_FCF*T29 | W29: =SUMPRODUCT($J$9:$S$9,$J$10:$S$10,Build_Flag*Base_Revenue*($J29:$S29*$J$11:$S$11-NWC_Pct*($J29:$S29-$I29:$R29))+(1-Build_Flag)*Base_FCF*$J29:$S29) | X29: =IF(Exit_Flag=1,Base_Revenue*T29*INDEX($J$12:$S$12,1,Forecast_Years)*Exit_Multiple/(1+WACC)^Forecast_Years,IF(TGR<WACC,V29*(1+TGR)/(WACC-TGR)/(1+WACC)^(Forecast_Years-Mid_Year),0))
B30: =B29+1 | C30: =IF(F29<Share_Price,E29,C29) | D30: =IF(F29<Share_Price,D29,E29) | E30: =(C30+D30)/2 | F30: =IF(Inputs_OK=1,(W30+X30+Net_Bridge)/Shares,0) | G30: =F30-Share_Price | I30: =1 | J30: =I30*(1+IF(J$8<=5,$E30,$E30+(TGR-$E30)*(J$8-5)/5)) | K30: =J30*(1+IF(K$8<=5,$E30,$E30+(TGR-$E30)*(K$8-5)/5)) | L30: =K30*(1+IF(L$8<=5,$E30,$E30+(TGR-$E30)*(L$8-5)/5)) | M30: =L30*(1+IF(M$8<=5,$E30,$E30+(TGR-$E30)*(M$8-5)/5)) | N30: =M30*(1+IF(N$8<=5,$E30,$E30+(TGR-$E30)*(N$8-5)/5)) | O30: =N30*(1+IF(O$8<=5,$E30,$E30+(TGR-$E30)*(O$8-5)/5)) | P30: =O30*(1+IF(P$8<=5,$E30,$E30+(TGR-$E30)*(P$8-5)/5)) | Q30: =P30*(1+IF(Q$8<=5,$E30,$E30+(TGR-$E30)*(Q$8-5)/5)) | ... S30: =R30*(1+IF(S$8<=5,$E30,$E30+(TGR-$E30)*(S$8-5)/5)) | T30: =INDEX($J30:$S30,1,Forecast_Years) | U30: =INDEX($I30:$S30,1,Forecast_Years) | V30: =Build_Flag*Base_Revenue*(T30*INDEX($J$11:$S$11,1,Forecast_Years)-NWC_Pct*(T30-U30))+(1-Build_Flag)*Base_FCF*T30 | W30: =SUMPRODUCT($J$9:$S$9,$J$10:$S$10,Build_Flag*Base_Revenue*($J30:$S30*$J$11:$S$11-NWC_Pct*($J30:$S30-$I30:$R30))+(1-Build_Flag)*Base_FCF*$J30:$S30) | X30: =IF(Exit_Flag=1,Base_Revenue*T30*INDEX($J$12:$S$12,1,Forecast_Years)*Exit_Multiple/(1+WACC)^Forecast_Years,IF(TGR<WACC,V30*(1+TGR)/(WACC-TGR)/(1+WACC)^(Forecast_Years-Mid_Year),0))
B31: =B30+1 | C31: =IF(F30<Share_Price,E30,C30) | D31: =IF(F30<Share_Price,D30,E30) | E31: =(C31+D31)/2 | F31: =IF(Inputs_OK=1,(W31+X31+Net_Bridge)/Shares,0) | G31: =F31-Share_Price | I31: =1 | J31: =I31*(1+IF(J$8<=5,$E31,$E31+(TGR-$E31)*(J$8-5)/5)) | K31: =J31*(1+IF(K$8<=5,$E31,$E31+(TGR-$E31)*(K$8-5)/5)) | L31: =K31*(1+IF(L$8<=5,$E31,$E31+(TGR-$E31)*(L$8-5)/5)) | M31: =L31*(1+IF(M$8<=5,$E31,$E31+(TGR-$E31)*(M$8-5)/5)) | N31: =M31*(1+IF(N$8<=5,$E31,$E31+(TGR-$E31)*(N$8-5)/5)) | O31: =N31*(1+IF(O$8<=5,$E31,$E31+(TGR-$E31)*(O$8-5)/5)) | P31: =O31*(1+IF(P$8<=5,$E31,$E31+(TGR-$E31)*(P$8-5)/5)) | Q31: =P31*(1+IF(Q$8<=5,$E31,$E31+(TGR-$E31)*(Q$8-5)/5)) | ... S31: =R31*(1+IF(S$8<=5,$E31,$E31+(TGR-$E31)*(S$8-5)/5)) | T31: =INDEX($J31:$S31,1,Forecast_Years) | U31: =INDEX($I31:$S31,1,Forecast_Years) | V31: =Build_Flag*Base_Revenue*(T31*INDEX($J$11:$S$11,1,Forecast_Years)-NWC_Pct*(T31-U31))+(1-Build_Flag)*Base_FCF*T31 | W31: =SUMPRODUCT($J$9:$S$9,$J$10:$S$10,Build_Flag*Base_Revenue*($J31:$S31*$J$11:$S$11-NWC_Pct*($J31:$S31-$I31:$R31))+(1-Build_Flag)*Base_FCF*$J31:$S31) | X31: =IF(Exit_Flag=1,Base_Revenue*T31*INDEX($J$12:$S$12,1,Forecast_Years)*Exit_Multiple/(1+WACC)^Forecast_Years,IF(TGR<WACC,V31*(1+TGR)/(WACC-TGR)/(1+WACC)^(Forecast_Years-Mid_Year),0))
B32: =B31+1 | C32: =IF(F31<Share_Price,E31,C31) | D32: =IF(F31<Share_Price,D31,E31) | E32: =(C32+D32)/2 | F32: =IF(Inputs_OK=1,(W32+X32+Net_Bridge)/Shares,0) | G32: =F32-Share_Price | I32: =1 | J32: =I32*(1+IF(J$8<=5,$E32,$E32+(TGR-$E32)*(J$8-5)/5)) | K32: =J32*(1+IF(K$8<=5,$E32,$E32+(TGR-$E32)*(K$8-5)/5)) | L32: =K32*(1+IF(L$8<=5,$E32,$E32+(TGR-$E32)*(L$8-5)/5)) | M32: =L32*(1+IF(M$8<=5,$E32,$E32+(TGR-$E32)*(M$8-5)/5)) | N32: =M32*(1+IF(N$8<=5,$E32,$E32+(TGR-$E32)*(N$8-5)/5)) | O32: =N32*(1+IF(O$8<=5,$E32,$E32+(TGR-$E32)*(O$8-5)/5)) | P32: =O32*(1+IF(P$8<=5,$E32,$E32+(TGR-$E32)*(P$8-5)/5)) | Q32: =P32*(1+IF(Q$8<=5,$E32,$E32+(TGR-$E32)*(Q$8-5)/5)) | ... S32: =R32*(1+IF(S$8<=5,$E32,$E32+(TGR-$E32)*(S$8-5)/5)) | T32: =INDEX($J32:$S32,1,Forecast_Years) | U32: =INDEX($I32:$S32,1,Forecast_Years) | V32: =Build_Flag*Base_Revenue*(T32*INDEX($J$11:$S$11,1,Forecast_Years)-NWC_Pct*(T32-U32))+(1-Build_Flag)*Base_FCF*T32 | W32: =SUMPRODUCT($J$9:$S$9,$J$10:$S$10,Build_Flag*Base_Revenue*($J32:$S32*$J$11:$S$11-NWC_Pct*($J32:$S32-$I32:$R32))+(1-Build_Flag)*Base_FCF*$J32:$S32) | X32: =IF(Exit_Flag=1,Base_Revenue*T32*INDEX($J$12:$S$12,1,Forecast_Years)*Exit_Multiple/(1+WACC)^Forecast_Years,IF(TGR<WACC,V32*(1+TGR)/(WACC-TGR)/(1+WACC)^(Forecast_Years-Mid_Year),0))
... B79: =B78+1 | C79: =IF(F78<Share_Price,E78,C78) | D79: =IF(F78<Share_Price,D78,E78) | E79: =(C79+D79)/2 | F79: =IF(Inputs_OK=1,(W79+X79+Net_Bridge)/Shares,0) | G79: =F79-Share_Price | I79: =1 | J79: =I79*(1+IF(J$8<=5,$E79,$E79+(TGR-$E79)*(J$8-5)/5)) | K79: =J79*(1+IF(K$8<=5,$E79,$E79+(TGR-$E79)*(K$8-5)/5)) | L79: =K79*(1+IF(L$8<=5,$E79,$E79+(TGR-$E79)*(L$8-5)/5)) | M79: =L79*(1+IF(M$8<=5,$E79,$E79+(TGR-$E79)*(M$8-5)/5)) | N79: =M79*(1+IF(N$8<=5,$E79,$E79+(TGR-$E79)*(N$8-5)/5)) | O79: =N79*(1+IF(O$8<=5,$E79,$E79+(TGR-$E79)*(O$8-5)/5)) | P79: =O79*(1+IF(P$8<=5,$E79,$E79+(TGR-$E79)*(P$8-5)/5)) | Q79: =P79*(1+IF(Q$8<=5,$E79,$E79+(TGR-$E79)*(Q$8-5)/5)) | ... S79: =R79*(1+IF(S$8<=5,$E79,$E79+(TGR-$E79)*(S$8-5)/5)) | T79: =INDEX($J79:$S79,1,Forecast_Years) | U79: =INDEX($I79:$S79,1,Forecast_Years) | V79: =Build_Flag*Base_Revenue*(T79*INDEX($J$11:$S$11,1,Forecast_Years)-NWC_Pct*(T79-U79))+(1-Build_Flag)*Base_FCF*T79 | W79: =SUMPRODUCT($J$9:$S$9,$J$10:$S$10,Build_Flag*Base_Revenue*($J79:$S79*$J$11:$S$11-NWC_Pct*($J79:$S79-$I79:$R79))+(1-Build_Flag)*Base_FCF*$J79:$S79) | X79: =IF(Exit_Flag=1,Base_Revenue*T79*INDEX($J$12:$S$12,1,Forecast_Years)*Exit_Multiple/(1+WACC)^Forecast_Years,IF(TGR<WACC,V79*(1+TGR)/(WACC-TGR)/(1+WACC)^(Forecast_Years-Mid_Year),0))
B80: Result | C80: =IF(F79<Share_Price,E79,C79) | D80: =IF(F79<Share_Price,D79,E79) | E80: =(C80+D80)/2
B81: Bounds and result
B82: At lower bound | E82: =Growth_Lower | F82: =IF(Inputs_OK=1,(W82+X82+Net_Bridge)/Shares,0) | I82: =1 | J82: =I82*(1+IF(J$8<=5,$E82,$E82+(TGR-$E82)*(J$8-5)/5)) | K82: =J82*(1+IF(K$8<=5,$E82,$E82+(TGR-$E82)*(K$8-5)/5)) | L82: =K82*(1+IF(L$8<=5,$E82,$E82+(TGR-$E82)*(L$8-5)/5)) | M82: =L82*(1+IF(M$8<=5,$E82,$E82+(TGR-$E82)*(M$8-5)/5)) | N82: =M82*(1+IF(N$8<=5,$E82,$E82+(TGR-$E82)*(N$8-5)/5)) | O82: =N82*(1+IF(O$8<=5,$E82,$E82+(TGR-$E82)*(O$8-5)/5)) | P82: =O82*(1+IF(P$8<=5,$E82,$E82+(TGR-$E82)*(P$8-5)/5)) | Q82: =P82*(1+IF(Q$8<=5,$E82,$E82+(TGR-$E82)*(Q$8-5)/5)) | ... S82: =R82*(1+IF(S$8<=5,$E82,$E82+(TGR-$E82)*(S$8-5)/5)) | T82: =INDEX($J82:$S82,1,Forecast_Years) | U82: =INDEX($I82:$S82,1,Forecast_Years) | V82: =Build_Flag*Base_Revenue*(T82*INDEX($J$11:$S$11,1,Forecast_Years)-NWC_Pct*(T82-U82))+(1-Build_Flag)*Base_FCF*T82 | W82: =SUMPRODUCT($J$9:$S$9,$J$10:$S$10,Build_Flag*Base_Revenue*($J82:$S82*$J$11:$S$11-NWC_Pct*($J82:$S82-$I82:$R82))+(1-Build_Flag)*Base_FCF*$J82:$S82) | X82: =IF(Exit_Flag=1,Base_Revenue*T82*INDEX($J$12:$S$12,1,Forecast_Years)*Exit_Multiple/(1+WACC)^Forecast_Years,IF(TGR<WACC,V82*(1+TGR)/(WACC-TGR)/(1+WACC)^(Forecast_Years-Mid_Year),0))
B83: At upper bound | E83: =Growth_Upper | F83: =IF(Inputs_OK=1,(W83+X83+Net_Bridge)/Shares,0) | I83: =1 | J83: =I83*(1+IF(J$8<=5,$E83,$E83+(TGR-$E83)*(J$8-5)/5)) | K83: =J83*(1+IF(K$8<=5,$E83,$E83+(TGR-$E83)*(K$8-5)/5)) | L83: =K83*(1+IF(L$8<=5,$E83,$E83+(TGR-$E83)*(L$8-5)/5)) | M83: =L83*(1+IF(M$8<=5,$E83,$E83+(TGR-$E83)*(M$8-5)/5)) | N83: =M83*(1+IF(N$8<=5,$E83,$E83+(TGR-$E83)*(N$8-5)/5)) | O83: =N83*(1+IF(O$8<=5,$E83,$E83+(TGR-$E83)*(O$8-5)/5)) | P83: =O83*(1+IF(P$8<=5,$E83,$E83+(TGR-$E83)*(P$8-5)/5)) | Q83: =P83*(1+IF(Q$8<=5,$E83,$E83+(TGR-$E83)*(Q$8-5)/5)) | ... S83: =R83*(1+IF(S$8<=5,$E83,$E83+(TGR-$E83)*(S$8-5)/5)) | T83: =INDEX($J83:$S83,1,Forecast_Years) | U83: =INDEX($I83:$S83,1,Forecast_Years) | V83: =Build_Flag*Base_Revenue*(T83*INDEX($J$11:$S$11,1,Forecast_Years)-NWC_Pct*(T83-U83))+(1-Build_Flag)*Base_FCF*T83 | W83: =SUMPRODUCT($J$9:$S$9,$J$10:$S$10,Build_Flag*Base_Revenue*($J83:$S83*$J$11:$S$11-NWC_Pct*($J83:$S83-$I83:$R83))+(1-Build_Flag)*Base_FCF*$J83:$S83) | X83: =IF(Exit_Flag=1,Base_Revenue*T83*INDEX($J$12:$S$12,1,Forecast_Years)*Exit_Multiple/(1+WACC)^Forecast_Years,IF(TGR<WACC,V83*(1+TGR)/(WACC-TGR)/(1+WACC)^(Forecast_Years-Mid_Year),0))
B84: At result | E84: =E80 | F84: =IF(Inputs_OK=1,(W84+X84+Net_Bridge)/Shares,0) | I84: =1 | J84: =I84*(1+IF(J$8<=5,$E84,$E84+(TGR-$E84)*(J$8-5)/5)) | K84: =J84*(1+IF(K$8<=5,$E84,$E84+(TGR-$E84)*(K$8-5)/5)) | L84: =K84*(1+IF(L$8<=5,$E84,$E84+(TGR-$E84)*(L$8-5)/5)) | M84: =L84*(1+IF(M$8<=5,$E84,$E84+(TGR-$E84)*(M$8-5)/5)) | N84: =M84*(1+IF(N$8<=5,$E84,$E84+(TGR-$E84)*(N$8-5)/5)) | O84: =N84*(1+IF(O$8<=5,$E84,$E84+(TGR-$E84)*(O$8-5)/5)) | P84: =O84*(1+IF(P$8<=5,$E84,$E84+(TGR-$E84)*(P$8-5)/5)) | Q84: =P84*(1+IF(Q$8<=5,$E84,$E84+(TGR-$E84)*(Q$8-5)/5)) | ... S84: =R84*(1+IF(S$8<=5,$E84,$E84+(TGR-$E84)*(S$8-5)/5)) | T84: =INDEX($J84:$S84,1,Forecast_Years) | U84: =INDEX($I84:$S84,1,Forecast_Years) | V84: =Build_Flag*Base_Revenue*(T84*INDEX($J$11:$S$11,1,Forecast_Years)-NWC_Pct*(T84-U84))+(1-Build_Flag)*Base_FCF*T84 | W84: =SUMPRODUCT($J$9:$S$9,$J$10:$S$10,Build_Flag*Base_Revenue*($J84:$S84*$J$11:$S$11-NWC_Pct*($J84:$S84-$I84:$R84))+(1-Build_Flag)*Base_FCF*$J84:$S84) | X84: =IF(Exit_Flag=1,Base_Revenue*T84*INDEX($J$12:$S$12,1,Forecast_Years)*Exit_Multiple/(1+WACC)^Forecast_Years,IF(TGR<WACC,V84*(1+TGR)/(WACC-TGR)/(1+WACC)^(Forecast_Years-Mid_Year),0))
B86: WACC search: bisection (free cash flows unchanged)
B87: Iteration | C87: Lower | D87: Upper | E87: Midpoint | F87: Value per share at midpoint | G87: Value less price
B88: =1 | C88: =IF(Exit_Flag=1,WACC_Lower,MAX(WACC_Lower,TGR+WACC_Spread)) | D88: =WACC_Upper | E88: =(C88+D88)/2 | F88: =IF(Inputs_OK=1,(SUMPRODUCT(FCF_Used,In_Forecast,1/(1+$E88)^Disc_Period)+IF(Exit_Flag=1,EBITDA_N*Exit_Multiple/(1+$E88)^Forecast_Years,IF(TGR<$E88,FCF_N*(1+TGR)/($E88-TGR)/(1+$E88)^(Forecast_Years-Mid_Year),0))+Net_Bridge)/Shares,0) | G88: =F88-Share_Price
B89: =B88+1 | C89: =IF(F88<Share_Price,C88,E88) | D89: =IF(F88<Share_Price,E88,D88) | E89: =(C89+D89)/2 | F89: =IF(Inputs_OK=1,(SUMPRODUCT(FCF_Used,In_Forecast,1/(1+$E89)^Disc_Period)+IF(Exit_Flag=1,EBITDA_N*Exit_Multiple/(1+$E89)^Forecast_Years,IF(TGR<$E89,FCF_N*(1+TGR)/($E89-TGR)/(1+$E89)^(Forecast_Years-Mid_Year),0))+Net_Bridge)/Shares,0) | G89: =F89-Share_Price
B90: =B89+1 | C90: =IF(F89<Share_Price,C89,E89) | D90: =IF(F89<Share_Price,E89,D89) | E90: =(C90+D90)/2 | F90: =IF(Inputs_OK=1,(SUMPRODUCT(FCF_Used,In_Forecast,1/(1+$E90)^Disc_Period)+IF(Exit_Flag=1,EBITDA_N*Exit_Multiple/(1+$E90)^Forecast_Years,IF(TGR<$E90,FCF_N*(1+TGR)/($E90-TGR)/(1+$E90)^(Forecast_Years-Mid_Year),0))+Net_Bridge)/Shares,0) | G90: =F90-Share_Price
B91: =B90+1 | C91: =IF(F90<Share_Price,C90,E90) | D91: =IF(F90<Share_Price,E90,D90) | E91: =(C91+D91)/2 | F91: =IF(Inputs_OK=1,(SUMPRODUCT(FCF_Used,In_Forecast,1/(1+$E91)^Disc_Period)+IF(Exit_Flag=1,EBITDA_N*Exit_Multiple/(1+$E91)^Forecast_Years,IF(TGR<$E91,FCF_N*(1+TGR)/($E91-TGR)/(1+$E91)^(Forecast_Years-Mid_Year),0))+Net_Bridge)/Shares,0) | G91: =F91-Share_Price
B92: =B91+1 | C92: =IF(F91<Share_Price,C91,E91) | D92: =IF(F91<Share_Price,E91,D91) | E92: =(C92+D92)/2 | F92: =IF(Inputs_OK=1,(SUMPRODUCT(FCF_Used,In_Forecast,1/(1+$E92)^Disc_Period)+IF(Exit_Flag=1,EBITDA_N*Exit_Multiple/(1+$E92)^Forecast_Years,IF(TGR<$E92,FCF_N*(1+TGR)/($E92-TGR)/(1+$E92)^(Forecast_Years-Mid_Year),0))+Net_Bridge)/Shares,0) | G92: =F92-Share_Price
B93: =B92+1 | C93: =IF(F92<Share_Price,C92,E92) | D93: =IF(F92<Share_Price,E92,D92) | E93: =(C93+D93)/2 | F93: =IF(Inputs_OK=1,(SUMPRODUCT(FCF_Used,In_Forecast,1/(1+$E93)^Disc_Period)+IF(Exit_Flag=1,EBITDA_N*Exit_Multiple/(1+$E93)^Forecast_Years,IF(TGR<$E93,FCF_N*(1+TGR)/($E93-TGR)/(1+$E93)^(Forecast_Years-Mid_Year),0))+Net_Bridge)/Shares,0) | G93: =F93-Share_Price
...

Sheet Checks
B1: Checks
B2: =IF(Company_Name="","Company not specified",Company_Name)&" | CHF m unless stated otherwise | Scenario: "&IF(Build_Flag=1,Scenario,"not used (direct FCF)")&" | Checks: "&Check_Status
B4: Model state
C5: Required inputs complete (1 = yes) | D5: =IF(AND(COUNT(TGR,Shares,Share_Price)=3,IF(Build_Flag=1,COUNT(Base_Revenue,Tax_Rate,DA_Pct,Capex_Pct,NWC_Pct)=5,COUNT(Base_FCF,FCF_Growth)=2),IF(Build_Flag=1,CHOOSE(Scenario_No,COUNT(Inputs!$F$38:$J$38),COUNT(Inputs!$F$39:$J$39),COUNT(Inputs!$F$40:$J$40))+CHOOSE(Scenario_No,COUNT(Inputs!$F$44:$J$44),COUNT(Inputs!$F$45:$J$45),COUNT(Inputs!$F$46:$J$46))=10,TRUE),IF(WACC_Source="CAPM",AND(COUNT(Rf,Beta_Input,MRP)=3,COUNT(Cost_Of_Debt,Target_DV,Tax_Rate)=3),COUNT(WACC_Direct)=1),IF(Exit_Flag=1,CHOOSE(Scenario_No,COUNT(Inputs!$E$50),COUNT(Inputs!$E$51),COUNT(Inputs!$E$52))=1,TRUE)),1,0)
C6: Inputs usable (1 = yes): complete and shares above zero | D6: =IF(AND(Inputs_Complete=1,N(Shares)>0),1,0)
C7: Valuation possible (1 = yes): terminal value method valid | D7: =IF(AND(Inputs_OK=1,IF(Exit_Flag=1,Build_Flag=1,TGR<WACC)),1,0)
B9: Checks
B10: # | C10: Check | D10: Value | E10: Status | F10: What is checked | G10: Message
B11: =1 | C11: Required inputs complete | D11: =Inputs_Complete | E11: =IF(Inputs_Complete=1,"OK","MISSING") | F11: Blue cells needed for the chosen switches | G11: =IF(OR(E11="WARNING",E11="ERROR",E11="INFO",E11="MISSING"),"Fill in the blue cells needed for the chosen switches on Inputs","")
B12: =B11+1 | C12: Diluted shares above zero | D12: =Shares | E12: =IF(Inputs_Complete=0,"n/a",IF(N(Shares)>0,"OK","ERROR")) | F12: Diluted shares on Inputs | G12: =IF(OR(E12="WARNING",E12="ERROR",E12="INFO",E12="MISSING"),"Enter a positive number of shares","")
B13: =B12+1 | C13: Terminal growth below WACC (perpetuity growth) | D13: =WACC-TGR | E13: =IF(Exit_Flag=1,"n/a",IF(Inputs_Complete=0,"n/a",IF(TGR<WACC,"OK","ERROR"))) | F13: WACC less terminal growth, must be positive | G13: =IF(OR(E13="WARNING",E13="ERROR",E13="INFO",E13="MISSING"),"Terminal growth must be below the WACC, otherwise the value is infinite","")
B14: =B13+1 | C14: Exit multiple used with the FCF build | D14: =Build_Flag | E14: =IF(Exit_Flag=0,"n/a",IF(Inputs_Complete=0,"n/a",IF(Build_Flag=1,"OK","ERROR"))) | F14: 1 = FCF build selected | G14: =IF(OR(E14="WARNING",E14="ERROR",E14="INFO",E14="MISSING"),"The exit multiple needs EBITDA: set the FCF source to Build","")
B15: =B14+1 | C15: Terminal growth at or below risk-free rate | D15: =TGR-Rf | E15: =IF(Exit_Flag=1,"n/a",IF(Inputs_Complete=0,"n/a",IF(TGR<=Rf,"OK","INFO"))) | F15: Terminal growth less risk-free rate | G15: =IF(OR(E15="WARNING",E15="ERROR",E15="INFO",E15="MISSING"),"Swiss risk-free rate currently very low. Many practitioners use a normalised rate","")
B16: =B15+1 | C16: Capital weights add up to 100% | D16: =WACC!E8+WACC!E9 | E16: =IF(Inputs_Complete=0,"n/a",IF(ABS(WACC!E8+WACC!E9-1)<Check_Tolerance,"OK","ERROR")) | F16: Debt and equity weights in the WACC | G16: =IF(OR(E16="WARNING",E16="ERROR",E16="INFO",E16="MISSING"),"Debt and equity weights do not add up to 100%","")
B17: =B16+1 | C17: Scenario selector valid | D17: =Scenario_No | E17: =IF(OR(Scenario="Bear",Scenario="Base",Scenario="Bull"),"OK","ERROR") | F17: Scenario is Bear, Base or Bull | G17: =IF(OR(E17="WARNING",E17="ERROR",E17="INFO",E17="MISSING"),"Choose Bear, Base or Bull on Inputs","")
B18: =B17+1 | C18: Forecast period is 5 or 10 years | D18: =Forecast_Years | E18: =IF(OR(Forecast_Years=5,Forecast_Years=10),"OK","ERROR") | F18: 5 or 10 years on Inputs | G18: =IF(OR(E18="WARNING",E18="ERROR",E18="INFO",E18="MISSING"),"Choose 5 or 10 years on Inputs","")
