Workbook
Name Min_Years: Settings!$C$5
Name Max_Years: Settings!$C$6
Name Step_Multiple: Settings!$C$7
Name Step_Leverage: Settings!$C$8
Name Check_Tolerance: Settings!$C$9
Name IRR_Tolerance: Settings!$C$10
Name Company_Name: Inputs!$E$5
Name Holding_Period: Inputs!$E$6
Name Entry_Method: Inputs!$E$7
Name Entry_Multiple: Inputs!$E$8
Name Entry_Amount: Inputs!$E$9
Name Exit_Mode: Inputs!$E$10
Name Exit_Multiple: Inputs!$E$11
Name Exit_Cost: Inputs!$E$12
Name Target_IRR: Inputs!$E$13
Name Op_Build: Inputs!$E$16
Name EBITDA_Input: Inputs!$E$18
Name EBITDA_Growth: Inputs!$E$19
Name DA_EBITDA: Inputs!$E$20
Name Capex_EBITDA: Inputs!$E$21
Name NWC_EBITDA: Inputs!$E$22
Name Revenue_0: Inputs!$E$24
Name Margin_0: Inputs!$E$25
Name DA_Revenue: Inputs!$E$26
Name Capex_Revenue: Inputs!$E$27
Name NWC_Revenue: Inputs!$E$28
Name Scenario: Inputs!$E$29
Name Growth_Bear: Inputs!$F$31:$J$31
Name Growth_Base: Inputs!$F$32:$J$32
Name Growth_Bull: Inputs!$F$33:$J$33
Name Margin_Bear: Inputs!$F$34:$J$34
Name Margin_Base: Inputs!$F$35:$J$35
Name Margin_Bull: Inputs!$F$36:$J$36
Name Year_Index: Inputs!$F$39:$L$39
Name SARON_Path: Inputs!$F$40:$L$40
Name SARON_Floor: Inputs!$E$41
Name Senior_Multiple: Inputs!$E$43
Name Senior_Margin: Inputs!$E$44
Name Senior_Amort: Inputs!$E$45
Name Sweep_Share: Inputs!$E$46
Name Junior_Multiple: Inputs!$E$48
Name Junior_Type: Inputs!$E$49
Name Junior_Rate: Inputs!$E$50
Name Junior_Margin: Inputs!$E$51
Name Junior_Payment: Inputs!$E$52
Name Fee_Transaction: Inputs!$E$54
Name Fee_Financing: Inputs!$E$55
Name Min_Cash: Inputs!$E$56
Name Cash_Rate: Inputs!$E$57
Name Tax_Rate: Inputs!$E$60
Name Interest_Deductible: Inputs!$E$61
Name Target_Net_Debt: Inputs!$E$64
Name Target_Other: Inputs!$E$65
Name Target_Shares: Inputs!$E$66
Name Target_VWAP: Inputs!$E$67
Name EBITDA_0: Transaction!$E$5
Name Entry_Multiple_Used: Transaction!$E$6
Name Purchase_EV: Transaction!$E$7
Name Exit_Multiple_Used: Transaction!$E$8
Name Holding_N: Transaction!$E$9

Sheet Cover
B1: Swiss LBO Model
B2: =IF(Company_Name="","Company not specified",Company_Name)&" | CHF m unless stated otherwise | Holding period: "&Holding_N&" years | Checks: "&Check_Status
B4: About this file
B5: Version | C5: v1.0.0, created 24 October 2026
B6: File | C6: Example with neutral illustrative values, the same as the start of the LBO calculator on noelwalpert.com
B7: Currency and units | C7: CHF. Amounts in millions, price per share in CHF, rates per year
B8: SARON | C8: Swiss National Bank, data.snb.ch, table zimoma, end of September 2026: -0.068%. Proposed for every year, overwrite on Inputs.
B10: Key results (implied values based on your assumptions)
B11: Model status | C11: =Check_Status
B12: IRR of the investor | C12: =IF(ISNUMBER(IRR),FIXED(IRR*100,1)&"% p.a.","n/a")
B13: Multiple on invested capital (MOIC) | C13: =IF(ISNUMBER(MOIC),FIXED(MOIC,2)&"x","n/a")
B14: Maximum entry multiple | C14: =IF(ISNUMBER(Max_Multiple),FIXED(Max_Multiple,1)&"x EBITDA (CHF "&FIXED(Max_EV,0)&"m) for "&FIXED(Target_IRR*100,1)&"% p.a.","n/a")
B15: Summary | C15: =Summary_Sentence
B17: Colour code
B18: 1.0 | C18: Blue: input
B19: 1.0 | C19: Black: formula
B20: 1.0 | C20: Green: link to another sheet
B22: Contents
B23: Inputs | C23: All assumptions: transaction, operations, financing, tax, price per share
B24: Transaction | C24: Purchase price, sources and uses of funds
B25: Operations | C25: EBITDA, depreciation, capital expenditure and net working capital year by year
B26: Debt Schedule | C26: Interest, tax, cash flow, mandatory amortisation and cash sweep
B27: Returns | C27: Exit, IRR, MOIC, maximum price and where the return comes from
B28: Sensitivities | C28: IRR by entry and exit multiple and by entry multiple and senior debt
B29: Checks | C29: Plausibility and integrity checks
B30: Settings | C30: Technical parameters
B32: Method notes
B33: Interest | C33: Interest is charged on the balance at the end of the previous year. This avoids a circular reference: the workbook needs no iterative calculation and no macro. Compared with interest on the average balance, the IRR is slightly lower (0.06 to 0.25 percentage points in the documented test cases).
B34: Price | C34: Debt is sized as a multiple of EBITDA year 0, so the debt schedule does not depend on the price. IRR and maximum price are closed formulas.
B35: Equity | C35: The investor loses at most the equity invested: the equity value at exit is never below zero.
B36: Tax | C36: Simplification: the model deducts interest from taxable profit. In Switzerland this depends on the structure. Usually a new acquisition company buys the target and takes on the loans. The interest then arises at the acquisition company and the profits at the target, and Swiss corporate income tax has no group taxation that offsets the two. If the two companies merge after the acquisition, interest on the acquisition loan is not deductible at the target according to a ruling of the Swiss Federal Supreme Court of 24 February 2026, if it has no link to the target's own business (9C_606/2025). Set this switch to No to see the effect. This is not tax advice.
B38: Sources and licence
B39: Website | C39: https://noelwalpert.com/tools/lbo-rechner
B40: Repository | C40: https://github.com/noelwalpert/swiss-financial-models
B41: Licence | C41: CC BY 4.0. You may share and adapt the model, also commercially, if you credit: Noel Walpert, noelwalpert.com
B43: Disclaimer
B44: This model is an illustration for educational and informational purposes. It is not investment, legal or tax advice and not a recommendation to buy or sell any security or company. IRR, MOIC and maximum price are implied values based on your assumptions. They are not a valuation opinion and not a prediction of a transaction price. Results depend entirely on the inputs.

Sheet Inputs
B1: Inputs
B2: =IF(Company_Name="","Company not specified",Company_Name)&" | CHF m unless stated otherwise | Holding period: "&Holding_N&" years | Checks: "&Check_Status
B4: A. Transaction
B5: Company name
B6: Holding period | C6: years | E6: 5
B7: Entry price entered as | E7: Multiple
B8: Entry multiple (EV / EBITDA year 0) | C8: x | E8: 10
B9: Entry enterprise value | C9: CHF m
B10: Exit multiple | E10: Same as entry
B11: Own exit multiple (EV / EBITDA at exit) | C11: x
B12: Selling costs at exit | C12: % of EV | E12: 0
B13: Target IRR of the investor | C13: % p.a. | E13: 0.2
B15: B. Operations
B16: Operating build | E16: EBITDA
B17: Build from EBITDA
B18: EBITDA year 0 | C18: CHF m | E18: 100
B19: EBITDA growth | C19: % p.a. | E19: 0.05
B20: Depreciation and amortisation | C20: % EBITDA | E20: 0.2
B21: Capital expenditure | C21: % EBITDA | E21: 0.2
B22: Change in net working capital | C22: % of ΔEBITDA | E22: 0
B23: Build from revenue
B24: Revenue year 0 | C24: CHF m | E24: 500
B25: EBITDA margin year 0 | C25: % | E25: 0.2
B26: Depreciation and amortisation | C26: % revenue | E26: 0.04
B27: Capital expenditure | C27: % revenue | E27: 0.04
B28: Net working capital | C28: % revenue | E28: 0.1
B29: Scenario | E29: Base
B30: Year | F30: =1 | G30: =F30+1 | H30: =G30+1 | I30: =H30+1 | J30: =I30+1
B31: Revenue growth, bear case | C31: % | F31: 0.02 | G31: 0.02 | H31: 0.02 | I31: 0.02 | J31: 0.02
B32: Revenue growth, base case | C32: % | F32: 0.05 | G32: 0.05 | H32: 0.05 | I32: 0.05 | J32: 0.05
B33: Revenue growth, bull case | C33: % | F33: 0.08 | G33: 0.08 | H33: 0.08 | I33: 0.08 | J33: 0.08
B34: EBITDA margin, bear case | C34: % | F34: 0.18 | G34: 0.18 | H34: 0.18 | I34: 0.18 | J34: 0.18
B35: EBITDA margin, base case | C35: % | F35: 0.2 | G35: 0.2 | H35: 0.2 | I35: 0.2 | J35: 0.2
B36: EBITDA margin, bull case | C36: % | F36: 0.22 | G36: 0.22 | H36: 0.22 | I36: 0.22 | J36: 0.22
B38: C. Financing
B39: Year | F39: =1 | G39: =F39+1 | H39: =G39+1 | I39: =H39+1 | J39: =I39+1 | K39: =J39+1 | L39: =K39+1
B40: SARON | C40: % p.a. | F40: -0.00067988 | G40: -0.00067988 | H40: -0.00067988 | I40: -0.00067988 | J40: -0.00067988 | K40: -0.00067988 | L40: -0.00067988
B41: SARON floor at 0% | E41: Yes
B42: Senior debt
B43: Senior debt | C43: x EBITDA | E43: 5
...

Sheet Transaction
B1: Transaction
B2: =IF(Company_Name="","Company not specified",Company_Name)&" | CHF m unless stated otherwise | Holding period: "&Holding_N&" years | Checks: "&Check_Status
B4: Purchase price
B5: EBITDA year 0 | C5: CHF m | E5: =IF(Op_Build="EBITDA",EBITDA_Input,Revenue_0*Margin_0)
B6: Entry multiple (EV / EBITDA year 0) | C6: x | E6: =IF(Entry_Method="Amount",IF(EBITDA_0>0,Entry_Amount/EBITDA_0,0),Entry_Multiple)
B7: Purchase price (enterprise value) | C7: CHF m | E7: =Entry_Multiple_Used*EBITDA_0
B8: Exit multiple | C8: x | E8: =IF(Exit_Mode="Own multiple",Exit_Multiple,Entry_Multiple_Used)
B9: Holding period used | C9: years | E9: =IF(ISNUMBER(Holding_Period),MIN(MAX(Holding_Period,Min_Years),Max_Years),Max_Years)
B11: Uses of funds | F11: % of total
B12: Purchase price (enterprise value) | C12: CHF m | E12: =Purchase_EV | F12: =IF(Uses_Total>0,E12/Uses_Total,"n/a")
B13: Transaction costs | C13: CHF m | E13: =Fee_Transaction*Purchase_EV | F13: =IF(Uses_Total>0,E13/Uses_Total,"n/a")
B14: Financing costs | C14: CHF m | E14: =Fee_Financing*(Senior_0+Junior_0) | F14: =IF(Uses_Total>0,E14/Uses_Total,"n/a")
B15: Cash on the balance sheet | C15: CHF m | E15: =Min_Cash | F15: =IF(Uses_Total>0,E15/Uses_Total,"n/a")
B16: Total uses | C16: CHF m | E16: =SUM(E12:E15)
B18: Sources of funds | F18: % of total
B19: Senior debt | C19: CHF m | E19: =Senior_Multiple*EBITDA_0 | F19: =IF(Sources_Total>0,E19/Sources_Total,"n/a")
B20: Junior debt | C20: CHF m | E20: =Junior_Multiple*EBITDA_0 | F20: =IF(Sources_Total>0,E20/Sources_Total,"n/a")
B21: Equity of the investor | C21: CHF m | E21: =Purchase_EV*(1+Fee_Transaction)+Financing_Costs+Cash_0-Senior_0-Junior_0 | F21: =IF(Sources_Total>0,E21/Sources_Total,"n/a")
B22: Total sources | C22: CHF m | E22: =E19+E20+E21
B24: Total debt / EBITDA year 0 | C24: x | E24: =IF(EBITDA_0>0,(Senior_0+Junior_0)/EBITDA_0,"n/a")

Sheet Operations
B1: Operations
B2: =IF(Company_Name="","Company not specified",Company_Name)&" | CHF m unless stated otherwise | Holding period: "&Holding_N&" years | Checks: "&Check_Status
B4: Year | E4: =0 | F4: =E4+1 | G4: =F4+1 | H4: =G4+1 | I4: =H4+1 | J4: =I4+1 | K4: =J4+1 | L4: =K4+1
B5: Within the holding period (1 = yes) | F5: =IF(F4<=Holding_N,1,0) | G5: =IF(G4<=Holding_N,1,0) | H5: =IF(H4<=Holding_N,1,0) | I5: =IF(I4<=Holding_N,1,0) | J5: =IF(J4<=Holding_N,1,0) | K5: =IF(K4<=Holding_N,1,0) | L5: =IF(L4<=Holding_N,1,0)
B7: Revenue (used only with the build from revenue)
B8: Revenue growth | C8: % | F8: =IF(Scenario="Bear",Inputs!F31,IF(Scenario="Base",Inputs!F32,Inputs!F33)) | G8: =IF(Scenario="Bear",Inputs!G31,IF(Scenario="Base",Inputs!G32,Inputs!G33)) | H8: =IF(Scenario="Bear",Inputs!H31,IF(Scenario="Base",Inputs!H32,Inputs!H33)) | I8: =IF(Scenario="Bear",Inputs!I31,IF(Scenario="Base",Inputs!I32,Inputs!I33)) | J8: =IF(Scenario="Bear",Inputs!J31,IF(Scenario="Base",Inputs!J32,Inputs!J33)) | K8: =IF(Scenario="Bear",Inputs!J31,IF(Scenario="Base",Inputs!J32,Inputs!J33)) | L8: =IF(Scenario="Bear",Inputs!J31,IF(Scenario="Base",Inputs!J32,Inputs!J33))
B9: Revenue | C9: CHF m | E9: =Revenue_0 | F9: =E9*(1+F8) | G9: =F9*(1+G8) | H9: =G9*(1+H8) | I9: =H9*(1+I8) | J9: =I9*(1+J8) | K9: =J9*(1+K8) | L9: =K9*(1+L8)
B10: EBITDA margin | C10: % | E10: =Margin_0 | F10: =IF(Scenario="Bear",Inputs!F34,IF(Scenario="Base",Inputs!F35,Inputs!F36)) | G10: =IF(Scenario="Bear",Inputs!G34,IF(Scenario="Base",Inputs!G35,Inputs!G36)) | H10: =IF(Scenario="Bear",Inputs!H34,IF(Scenario="Base",Inputs!H35,Inputs!H36)) | I10: =IF(Scenario="Bear",Inputs!I34,IF(Scenario="Base",Inputs!I35,Inputs!I36)) | J10: =IF(Scenario="Bear",Inputs!J34,IF(Scenario="Base",Inputs!J35,Inputs!J36)) | K10: =IF(Scenario="Bear",Inputs!J34,IF(Scenario="Base",Inputs!J35,Inputs!J36)) | L10: =IF(Scenario="Bear",Inputs!J34,IF(Scenario="Base",Inputs!J35,Inputs!J36))
B12: EBITDA and cash items
B13: EBITDA | C13: CHF m | E13: =EBITDA_0 | F13: =IF(Op_Build="EBITDA",E13*(1+EBITDA_Growth),F9*F10) | G13: =IF(Op_Build="EBITDA",F13*(1+EBITDA_Growth),G9*G10) | H13: =IF(Op_Build="EBITDA",G13*(1+EBITDA_Growth),H9*H10) | I13: =IF(Op_Build="EBITDA",H13*(1+EBITDA_Growth),I9*I10) | J13: =IF(Op_Build="EBITDA",I13*(1+EBITDA_Growth),J9*J10) | K13: =IF(Op_Build="EBITDA",J13*(1+EBITDA_Growth),K9*K10) | L13: =IF(Op_Build="EBITDA",K13*(1+EBITDA_Growth),L9*L10)
B14: Depreciation and amortisation | C14: CHF m | F14: =IF(Op_Build="EBITDA",DA_EBITDA*F13,DA_Revenue*F9) | G14: =IF(Op_Build="EBITDA",DA_EBITDA*G13,DA_Revenue*G9) | H14: =IF(Op_Build="EBITDA",DA_EBITDA*H13,DA_Revenue*H9) | I14: =IF(Op_Build="EBITDA",DA_EBITDA*I13,DA_Revenue*I9) | J14: =IF(Op_Build="EBITDA",DA_EBITDA*J13,DA_Revenue*J9) | K14: =IF(Op_Build="EBITDA",DA_EBITDA*K13,DA_Revenue*K9) | L14: =IF(Op_Build="EBITDA",DA_EBITDA*L13,DA_Revenue*L9)
B15: EBIT | C15: CHF m | F15: =F13-F14 | G15: =G13-G14 | H15: =H13-H14 | I15: =I13-I14 | J15: =J13-J14 | K15: =K13-K14 | L15: =L13-L14
B16: Capital expenditure | C16: CHF m | F16: =IF(Op_Build="EBITDA",Capex_EBITDA*F13,Capex_Revenue*F9) | G16: =IF(Op_Build="EBITDA",Capex_EBITDA*G13,Capex_Revenue*G9) | H16: =IF(Op_Build="EBITDA",Capex_EBITDA*H13,Capex_Revenue*H9) | I16: =IF(Op_Build="EBITDA",Capex_EBITDA*I13,Capex_Revenue*I9) | J16: =IF(Op_Build="EBITDA",Capex_EBITDA*J13,Capex_Revenue*J9) | K16: =IF(Op_Build="EBITDA",Capex_EBITDA*K13,Capex_Revenue*K9) | L16: =IF(Op_Build="EBITDA",Capex_EBITDA*L13,Capex_Revenue*L9)
B17: Change in net working capital | C17: CHF m | F17: =IF(Op_Build="EBITDA",NWC_EBITDA*(F13-E13),NWC_Revenue*(F9-E9)) | G17: =IF(Op_Build="EBITDA",NWC_EBITDA*(G13-F13),NWC_Revenue*(G9-F9)) | H17: =IF(Op_Build="EBITDA",NWC_EBITDA*(H13-G13),NWC_Revenue*(H9-G9)) | I17: =IF(Op_Build="EBITDA",NWC_EBITDA*(I13-H13),NWC_Revenue*(I9-H9)) | J17: =IF(Op_Build="EBITDA",NWC_EBITDA*(J13-I13),NWC_Revenue*(J9-I9)) | K17: =IF(Op_Build="EBITDA",NWC_EBITDA*(K13-J13),NWC_Revenue*(K9-J9)) | L17: =IF(Op_Build="EBITDA",NWC_EBITDA*(L13-K13),NWC_Revenue*(L9-K9))

Sheet Debt Schedule
B1: Debt Schedule
B2: =IF(Company_Name="","Company not specified",Company_Name)&" | CHF m unless stated otherwise | Holding period: "&Holding_N&" years | Checks: "&Check_Status
B4: Year | E4: =0 | F4: =E4+1 | G4: =F4+1 | H4: =G4+1 | I4: =H4+1 | J4: =I4+1 | K4: =J4+1 | L4: =K4+1
B5: Interest rates
B6: SARON | C6: % p.a. | F6: =Inputs!F40 | G6: =Inputs!G40 | H6: =Inputs!H40 | I6: =Inputs!I40 | J6: =Inputs!J40 | K6: =Inputs!K40 | L6: =Inputs!L40
B7: SARON used (with floor if chosen) | C7: % p.a. | F7: =IF(SARON_Floor="Yes",MAX(F6,0),F6) | G7: =IF(SARON_Floor="Yes",MAX(G6,0),G6) | H7: =IF(SARON_Floor="Yes",MAX(H6,0),H6) | I7: =IF(SARON_Floor="Yes",MAX(I6,0),I6) | J7: =IF(SARON_Floor="Yes",MAX(J6,0),J6) | K7: =IF(SARON_Floor="Yes",MAX(K6,0),K6) | L7: =IF(SARON_Floor="Yes",MAX(L6,0),L6)
B8: Senior debt: SARON plus margin | C8: % p.a. | F8: =F7+Senior_Margin | G8: =G7+Senior_Margin | H8: =H7+Senior_Margin | I8: =I7+Senior_Margin | J8: =J7+Senior_Margin | K8: =K7+Senior_Margin | L8: =L7+Senior_Margin
B9: Junior debt | C9: % p.a. | F9: =IF(Junior_Type="Fixed",Junior_Rate,F7+Junior_Margin) | G9: =IF(Junior_Type="Fixed",Junior_Rate,G7+Junior_Margin) | H9: =IF(Junior_Type="Fixed",Junior_Rate,H7+Junior_Margin) | I9: =IF(Junior_Type="Fixed",Junior_Rate,I7+Junior_Margin) | J9: =IF(Junior_Type="Fixed",Junior_Rate,J7+Junior_Margin) | K9: =IF(Junior_Type="Fixed",Junior_Rate,K7+Junior_Margin) | L9: =IF(Junior_Type="Fixed",Junior_Rate,L7+Junior_Margin)
B11: Senior debt
B12: Opening balance | C12: CHF m | F12: =E16 | G12: =F16 | H12: =G16 | I12: =H16 | J12: =I16 | K12: =J16 | L12: =K16
B13: Interest (rate × opening balance) | C13: CHF m | F13: =F8*F12 | G13: =G8*G12 | H13: =H8*H12 | I13: =I8*I12 | J13: =J8*J12 | K13: =K8*K12 | L13: =L8*L12
B14: Mandatory amortisation | C14: CHF m | F14: =MIN(F12,Senior_Amort*Senior_0) | G14: =MIN(G12,Senior_Amort*Senior_0) | H14: =MIN(H12,Senior_Amort*Senior_0) | I14: =MIN(I12,Senior_Amort*Senior_0) | J14: =MIN(J12,Senior_Amort*Senior_0) | K14: =MIN(K12,Senior_Amort*Senior_0) | L14: =MIN(L12,Senior_Amort*Senior_0)
B15: Cash sweep | C15: CHF m | F15: =MIN(F12-F14,Sweep_Share*F43) | G15: =MIN(G12-G14,Sweep_Share*G43) | H15: =MIN(H12-H14,Sweep_Share*H43) | I15: =MIN(I12-I14,Sweep_Share*I43) | J15: =MIN(J12-J14,Sweep_Share*J43) | K15: =MIN(K12-K14,Sweep_Share*K43) | L15: =MIN(L12-L14,Sweep_Share*L43)
B16: Closing balance | C16: CHF m | E16: =Senior_0 | F16: =F12-F14-F15 | G16: =G12-G14-G15 | H16: =H12-H14-H15 | I16: =I12-I14-I15 | J16: =J12-J14-J15 | K16: =K12-K14-K15 | L16: =L12-L14-L15
B18: Junior debt
B19: Opening balance | C19: CHF m | F19: =E22 | G19: =F22 | H19: =G22 | I19: =H22 | J19: =I22 | K19: =J22 | L19: =K22
B20: Interest (rate × opening balance) | C20: CHF m | F20: =F9*F19 | G20: =G9*G19 | H20: =H9*H19 | I20: =I9*I19 | J20: =J9*J19 | K20: =K9*K19 | L20: =L9*L19
B21: of which payment in kind (added to the loan) | C21: CHF m | F21: =IF(Junior_Payment="PIK",F20,0) | G21: =IF(Junior_Payment="PIK",G20,0) | H21: =IF(Junior_Payment="PIK",H20,0) | I21: =IF(Junior_Payment="PIK",I20,0) | J21: =IF(Junior_Payment="PIK",J20,0) | K21: =IF(Junior_Payment="PIK",K20,0) | L21: =IF(Junior_Payment="PIK",L20,0)
B22: Closing balance | C22: CHF m | E22: =Junior_0 | F22: =F19+F21 | G22: =G19+G21 | H22: =H19+H21 | I22: =I19+I21 | J22: =J19+J21 | K22: =K19+K21 | L22: =L19+L21
B24: Cash
B25: Opening balance | C25: CHF m | F25: =E27 | G25: =F27 | H25: =G27 | I25: =H27 | J25: =I27 | K25: =J27 | L25: =K27
B26: Interest income | C26: CHF m | F26: =Cash_Rate*MAX(0,F25) | G26: =Cash_Rate*MAX(0,G25) | H26: =Cash_Rate*MAX(0,H25) | I26: =Cash_Rate*MAX(0,I25) | J26: =Cash_Rate*MAX(0,J25) | K26: =Cash_Rate*MAX(0,K25) | L26: =Cash_Rate*MAX(0,L25)
B27: Closing balance | C27: CHF m | E27: =Cash_0 | F27: =F25+F42-F15 | G27: =G25+G42-G15 | H27: =H25+H42-H15 | I27: =I25+I42-I15 | J27: =J25+J42-J15 | K27: =K25+K42-K15 | L27: =L25+L42-L15
B29: Tax
B30: EBIT | C30: CHF m | F30: =Operations!F15 | G30: =Operations!G15 | H30: =Operations!H15 | I30: =Operations!I15 | J30: =Operations!J15 | K30: =Operations!K15 | L30: =Operations!L15
B31: Taxable profit | C31: CHF m | F31: =F30+F26-IF(Interest_Deductible="Yes",F13+F20,0) | G31: =G30+G26-IF(Interest_Deductible="Yes",G13+G20,0) | H31: =H30+H26-IF(Interest_Deductible="Yes",H13+H20,0) | I31: =I30+I26-IF(Interest_Deductible="Yes",I13+I20,0) | J31: =J30+J26-IF(Interest_Deductible="Yes",J13+J20,0) | K31: =K30+K26-IF(Interest_Deductible="Yes",K13+K20,0) | L31: =L30+L26-IF(Interest_Deductible="Yes",L13+L20,0)
B32: Taxes | C32: CHF m | F32: =Tax_Rate*MAX(0,F31) | G32: =Tax_Rate*MAX(0,G31) | H32: =Tax_Rate*MAX(0,H31) | I32: =Tax_Rate*MAX(0,I31) | J32: =Tax_Rate*MAX(0,J31) | K32: =Tax_Rate*MAX(0,K31) | L32: =Tax_Rate*MAX(0,L31)
B34: Cash flow and debt service
B35: EBITDA | C35: CHF m | F35: =Operations!F13 | G35: =Operations!G13 | H35: =Operations!H13 | I35: =Operations!I13 | J35: =Operations!J13 | K35: =Operations!K13 | L35: =Operations!L13
B36: less taxes | C36: CHF m | F36: =F32 | G36: =G32 | H36: =H32 | I36: =I32 | J36: =J32 | K36: =K32 | L36: =L32
B37: less capital expenditure | C37: CHF m | F37: =Operations!F16 | G37: =Operations!G16 | H37: =Operations!H16 | I37: =Operations!I16 | J37: =Operations!J16 | K37: =Operations!K16 | L37: =Operations!L16
B38: less change in net working capital | C38: CHF m | F38: =Operations!F17 | G38: =Operations!G17 | H38: =Operations!H17 | I38: =Operations!I17 | J38: =Operations!J17 | K38: =Operations!K17 | L38: =Operations!L17
B39: Cash flow before financing | C39: CHF m | F39: =F35-F36-F37-F38 | G39: =G35-G36-G37-G38 | H39: =H35-H36-H37-H38 | I39: =I35-I36-I37-I38 | J39: =J35-J36-J37-J38 | K39: =K35-K36-K37-K38 | L39: =L35-L36-L37-L38
B40: less interest paid in cash, net of interest income | C40: CHF m | F40: =F13+(F20-F21)-F26 | G40: =G13+(G20-G21)-G26 | H40: =H13+(H20-H21)-H26 | I40: =I13+(I20-I21)-I26 | J40: =J13+(J20-J21)-J26 | K40: =K13+(K20-K21)-K26 | L40: =L13+(L20-L21)-L26
B41: less mandatory amortisation | C41: CHF m | F41: =F14 | G41: =G14 | H41: =H14 | I41: =I14 | J41: =J14 | K41: =K14 | L41: =L14
B42: Cash flow after debt service | C42: CHF m | F42: =F39-F40-F41 | G42: =G39-G40-G41 | H42: =H39-H40-H41 | I42: =I39-I40-I41 | J42: =J39-J40-J41 | K42: =K39-K40-K41 | L42: =L39-L40-L41
B43: Cash available for the sweep | C43: CHF m | F43: =MAX(0,F25+F42-Min_Cash) | G43: =MAX(0,G25+G42-Min_Cash) | H43: =MAX(0,H25+H42-Min_Cash) | I43: =MAX(0,I25+I42-Min_Cash) | J43: =MAX(0,J25+J42-Min_Cash) | K43: =MAX(0,K25+K42-Min_Cash) | L43: =MAX(0,L25+L42-Min_Cash)
B45: Credit metrics
B46: Net debt | C46: CHF m | E46: =Senior_0+Junior_0-Cash_0 | F46: =F16+F22-F27 | G46: =G16+G22-G27 | H46: =H16+H22-H27 | I46: =I16+I22-I27 | J46: =J16+J22-J27 | K46: =K16+K22-K27 | L46: =L16+L22-L27
B47: Net debt / EBITDA | C47: x | F47: =IF(F35>0,F46/F35,"n/a") | G47: =IF(G35>0,G46/G35,"n/a") | H47: =IF(H35>0,H46/H35,"n/a") | I47: =IF(I35>0,I46/I35,"n/a") | J47: =IF(J35>0,J46/J35,"n/a") | K47: =IF(K35>0,K46/K35,"n/a") | L47: =IF(L35>0,L46/L35,"n/a")
...

Sheet Returns
B1: Returns
B2: =IF(Company_Name="","Company not specified",Company_Name)&" | CHF m unless stated otherwise | Holding period: "&Holding_N&" years | Checks: "&Check_Status
B4: Exit
B5: Holding period | C5: years | E5: =Holding_N
B6: EBITDA at exit | C6: CHF m | E6: =INDEX(Operations!$F$13:$L$13,Holding_N)
B7: Exit multiple | C7: x | E7: =Exit_Multiple_Used
B8: Enterprise value at exit | C8: CHF m | E8: =Exit_Multiple_Used*EBITDA_Exit
B9: Selling costs | C9: CHF m | E9: =Exit_Cost*Exit_EV
B10: Net debt at exit | C10: CHF m | E10: =INDEX(Net_Debt_Path,Holding_N)
B11: Exit value less net debt | C11: CHF m | E11: =Exit_Multiple_Used*EBITDA_Exit*(1-Exit_Cost)-Net_Debt_Exit
B12: Equity value at exit | C12: CHF m | E12: =MAX(0,Equity_Exit_Raw)
B14: Returns of the investor
B15: Equity invested at closing | C15: CHF m | E15: =Equity_In
B16: Multiple on invested capital (MOIC) | C16: x | E16: =IF(Equity_In>0,Equity_Exit/Equity_In,"n/a")
B17: Internal rate of return (IRR) | C17: % p.a. | E17: =IF(Equity_In>0,(Equity_Exit/Equity_In)^(1/Holding_N)-1,"n/a")
B19: Maximum price for the target IRR: implied value based on your assumptions
B20: Target IRR | C20: % p.a. | E20: =Target_IRR
B21: Maximum equity invested | C21: CHF m | E21: =IF(Equity_Exit>0,Equity_Exit/(1+Target_IRR)^Holding_N,"n/a")
B22: Maximum purchase price (enterprise value) | C22: CHF m | E22: =IF(ISNUMBER(Max_Equity),IF(Max_Equity+Senior_0+Junior_0-Financing_Costs-Cash_0>0,(Max_Equity+Senior_0+Junior_0-Financing_Costs-Cash_0)/(1+Fee_Transaction),"n/a"),"n/a")
B23: Maximum entry multiple (EV / EBITDA year 0) | C23: x | E23: =IF(ISNUMBER(Max_EV),Max_EV/EBITDA_0,"n/a")
B25: Where the return comes from
B26: EBITDA growth | C26: CHF m | E26: =Entry_Multiple_Used*(EBITDA_Exit-EBITDA_0)
B27: Change in multiple | C27: CHF m | E27: =(Exit_Multiple_Used-Entry_Multiple_Used)*EBITDA_Exit
B28: Debt paydown and cash build-up | C28: CHF m | E28: =Senior_0+Junior_0-Cash_0-Net_Debt_Exit
B29: Costs | C29: CHF m | E29: =-(Fee_Transaction*Purchase_EV+Financing_Costs+Exit_Cost*Exit_EV)
B30: Loss beyond the equity (borne by the lenders) | C30: CHF m | E30: =Equity_Exit-Equity_Exit_Raw
B31: Gain of the investor (sum of the parts) | C31: CHF m | E31: =SUM(E26:E30)
B32: Gain of the investor (exit less invested) | C32: CHF m | E32: =Equity_Exit-Equity_In
B34: Price per share (optional): implied value based on your assumptions
B35: Price per share at the entry price | C35: CHF | E35: =IF(Target_Shares>0,(Purchase_EV-Target_Net_Debt-Target_Other)/Target_Shares,"n/a")
B36: Premium to the 60-day VWAP | C36: % | E36: =IF(AND(ISNUMBER(Price_Per_Share),Target_VWAP>0),Price_Per_Share/Target_VWAP-1,"n/a")
B37: Maximum price per share for the target IRR | C37: CHF | E37: =IF(AND(Target_Shares>0,ISNUMBER(Max_EV)),(Max_EV-Target_Net_Debt-Target_Other)/Target_Shares,"n/a")
B38: Maximum premium to the 60-day VWAP | C38: % | E38: =IF(AND(ISNUMBER(Max_Price_Per_Share),Target_VWAP>0),Max_Price_Per_Share/Target_VWAP-1,"n/a")
B40: Summary
B41: =IF(AND(Inputs_Complete=1,ISNUMBER(IRR)),"At an entry price of "&FIXED(Entry_Multiple_Used,1)&"x EBITDA the investor earns an IRR of "&FIXED(IRR*100,1)&"% p.a. ("&FIXED(MOIC,2)&"x the equity) based on your assumptions. "&IF(ISNUMBER(Max_Multiple),"To reach "&FIXED(Target_IRR*100,1)&"% p.a., the maximum price is "&FIXED(Max_Multiple,1)&"x EBITDA.","No price reaches the target IRR of "&FIXED(Target_IRR*100,1)&"% p.a."),"Fill in the blue cells on Inputs.")
B44: Cash flows of the investor (for the IRR cross-check on Checks)
B45: Year | E45: =0 | F45: =E45+1 | G45: =F45+1 | H45: =G45+1 | I45: =H45+1 | J45: =I45+1 | K45: =J45+1 | L45: =K45+1
B46: Cash flow to and from the investor | C46: CHF m | E46: =-Equity_In | F46: =IF(F45=Holding_N,Equity_Exit,0) | G46: =IF(G45=Holding_N,Equity_Exit,0) | H46: =IF(H45=Holding_N,Equity_Exit,0) | I46: =IF(I45=Holding_N,Equity_Exit,0) | J46: =IF(J45=Holding_N,Equity_Exit,0) | K46: =IF(K45=Holding_N,Equity_Exit,0) | L46: =IF(L45=Holding_N,Equity_Exit,0)

Sheet Sensitivities
B1: Sensitivities
B2: =IF(Company_Name="","Company not specified",Company_Name)&" | CHF m unless stated otherwise | Holding period: "&Holding_N&" years | Checks: "&Check_Status
B4: Table 1: IRR by entry multiple (rows) and exit multiple (columns)
D6: Entry / exit | E6: =F6-Step_Multiple | F6: =G6-Step_Multiple | G6: =Exit_Multiple_Used | H6: =G6+Step_Multiple | I6: =H6+Step_Multiple
B7: The exit multiple does not change the debt schedule, so each cell is a closed formula. | D7: =D8-Step_Multiple | E7: =IF($D7*EBITDA_0*(1+Fee_Transaction)+Financing_Costs+Cash_0-Senior_0-Junior_0>0,(MAX(0,E$6*EBITDA_Exit*(1-Exit_Cost)-Net_Debt_Exit)/($D7*EBITDA_0*(1+Fee_Transaction)+Financing_Costs+Cash_0-Senior_0-Junior_0))^(1/Holding_N)-1,"n/a") | F7: =IF($D7*EBITDA_0*(1+Fee_Transaction)+Financing_Costs+Cash_0-Senior_0-Junior_0>0,(MAX(0,F$6*EBITDA_Exit*(1-Exit_Cost)-Net_Debt_Exit)/($D7*EBITDA_0*(1+Fee_Transaction)+Financing_Costs+Cash_0-Senior_0-Junior_0))^(1/Holding_N)-1,"n/a") | G7: =IF($D7*EBITDA_0*(1+Fee_Transaction)+Financing_Costs+Cash_0-Senior_0-Junior_0>0,(MAX(0,G$6*EBITDA_Exit*(1-Exit_Cost)-Net_Debt_Exit)/($D7*EBITDA_0*(1+Fee_Transaction)+Financing_Costs+Cash_0-Senior_0-Junior_0))^(1/Holding_N)-1,"n/a") | H7: =IF($D7*EBITDA_0*(1+Fee_Transaction)+Financing_Costs+Cash_0-Senior_0-Junior_0>0,(MAX(0,H$6*EBITDA_Exit*(1-Exit_Cost)-Net_Debt_Exit)/($D7*EBITDA_0*(1+Fee_Transaction)+Financing_Costs+Cash_0-Senior_0-Junior_0))^(1/Holding_N)-1,"n/a") | I7: =IF($D7*EBITDA_0*(1+Fee_Transaction)+Financing_Costs+Cash_0-Senior_0-Junior_0>0,(MAX(0,I$6*EBITDA_Exit*(1-Exit_Cost)-Net_Debt_Exit)/($D7*EBITDA_0*(1+Fee_Transaction)+Financing_Costs+Cash_0-Senior_0-Junior_0))^(1/Holding_N)-1,"n/a")
D8: =D9-Step_Multiple | E8: =IF($D8*EBITDA_0*(1+Fee_Transaction)+Financing_Costs+Cash_0-Senior_0-Junior_0>0,(MAX(0,E$6*EBITDA_Exit*(1-Exit_Cost)-Net_Debt_Exit)/($D8*EBITDA_0*(1+Fee_Transaction)+Financing_Costs+Cash_0-Senior_0-Junior_0))^(1/Holding_N)-1,"n/a") | F8: =IF($D8*EBITDA_0*(1+Fee_Transaction)+Financing_Costs+Cash_0-Senior_0-Junior_0>0,(MAX(0,F$6*EBITDA_Exit*(1-Exit_Cost)-Net_Debt_Exit)/($D8*EBITDA_0*(1+Fee_Transaction)+Financing_Costs+Cash_0-Senior_0-Junior_0))^(1/Holding_N)-1,"n/a") | G8: =IF($D8*EBITDA_0*(1+Fee_Transaction)+Financing_Costs+Cash_0-Senior_0-Junior_0>0,(MAX(0,G$6*EBITDA_Exit*(1-Exit_Cost)-Net_Debt_Exit)/($D8*EBITDA_0*(1+Fee_Transaction)+Financing_Costs+Cash_0-Senior_0-Junior_0))^(1/Holding_N)-1,"n/a") | H8: =IF($D8*EBITDA_0*(1+Fee_Transaction)+Financing_Costs+Cash_0-Senior_0-Junior_0>0,(MAX(0,H$6*EBITDA_Exit*(1-Exit_Cost)-Net_Debt_Exit)/($D8*EBITDA_0*(1+Fee_Transaction)+Financing_Costs+Cash_0-Senior_0-Junior_0))^(1/Holding_N)-1,"n/a") | I8: =IF($D8*EBITDA_0*(1+Fee_Transaction)+Financing_Costs+Cash_0-Senior_0-Junior_0>0,(MAX(0,I$6*EBITDA_Exit*(1-Exit_Cost)-Net_Debt_Exit)/($D8*EBITDA_0*(1+Fee_Transaction)+Financing_Costs+Cash_0-Senior_0-Junior_0))^(1/Holding_N)-1,"n/a")
D9: =Entry_Multiple_Used | E9: =IF($D9*EBITDA_0*(1+Fee_Transaction)+Financing_Costs+Cash_0-Senior_0-Junior_0>0,(MAX(0,E$6*EBITDA_Exit*(1-Exit_Cost)-Net_Debt_Exit)/($D9*EBITDA_0*(1+Fee_Transaction)+Financing_Costs+Cash_0-Senior_0-Junior_0))^(1/Holding_N)-1,"n/a") | F9: =IF($D9*EBITDA_0*(1+Fee_Transaction)+Financing_Costs+Cash_0-Senior_0-Junior_0>0,(MAX(0,F$6*EBITDA_Exit*(1-Exit_Cost)-Net_Debt_Exit)/($D9*EBITDA_0*(1+Fee_Transaction)+Financing_Costs+Cash_0-Senior_0-Junior_0))^(1/Holding_N)-1,"n/a") | G9: =IF($D9*EBITDA_0*(1+Fee_Transaction)+Financing_Costs+Cash_0-Senior_0-Junior_0>0,(MAX(0,G$6*EBITDA_Exit*(1-Exit_Cost)-Net_Debt_Exit)/($D9*EBITDA_0*(1+Fee_Transaction)+Financing_Costs+Cash_0-Senior_0-Junior_0))^(1/Holding_N)-1,"n/a") | H9: =IF($D9*EBITDA_0*(1+Fee_Transaction)+Financing_Costs+Cash_0-Senior_0-Junior_0>0,(MAX(0,H$6*EBITDA_Exit*(1-Exit_Cost)-Net_Debt_Exit)/($D9*EBITDA_0*(1+Fee_Transaction)+Financing_Costs+Cash_0-Senior_0-Junior_0))^(1/Holding_N)-1,"n/a") | I9: =IF($D9*EBITDA_0*(1+Fee_Transaction)+Financing_Costs+Cash_0-Senior_0-Junior_0>0,(MAX(0,I$6*EBITDA_Exit*(1-Exit_Cost)-Net_Debt_Exit)/($D9*EBITDA_0*(1+Fee_Transaction)+Financing_Costs+Cash_0-Senior_0-Junior_0))^(1/Holding_N)-1,"n/a")
D10: =D9+Step_Multiple | E10: =IF($D10*EBITDA_0*(1+Fee_Transaction)+Financing_Costs+Cash_0-Senior_0-Junior_0>0,(MAX(0,E$6*EBITDA_Exit*(1-Exit_Cost)-Net_Debt_Exit)/($D10*EBITDA_0*(1+Fee_Transaction)+Financing_Costs+Cash_0-Senior_0-Junior_0))^(1/Holding_N)-1,"n/a") | F10: =IF($D10*EBITDA_0*(1+Fee_Transaction)+Financing_Costs+Cash_0-Senior_0-Junior_0>0,(MAX(0,F$6*EBITDA_Exit*(1-Exit_Cost)-Net_Debt_Exit)/($D10*EBITDA_0*(1+Fee_Transaction)+Financing_Costs+Cash_0-Senior_0-Junior_0))^(1/Holding_N)-1,"n/a") | G10: =IF($D10*EBITDA_0*(1+Fee_Transaction)+Financing_Costs+Cash_0-Senior_0-Junior_0>0,(MAX(0,G$6*EBITDA_Exit*(1-Exit_Cost)-Net_Debt_Exit)/($D10*EBITDA_0*(1+Fee_Transaction)+Financing_Costs+Cash_0-Senior_0-Junior_0))^(1/Holding_N)-1,"n/a") | H10: =IF($D10*EBITDA_0*(1+Fee_Transaction)+Financing_Costs+Cash_0-Senior_0-Junior_0>0,(MAX(0,H$6*EBITDA_Exit*(1-Exit_Cost)-Net_Debt_Exit)/($D10*EBITDA_0*(1+Fee_Transaction)+Financing_Costs+Cash_0-Senior_0-Junior_0))^(1/Holding_N)-1,"n/a") | I10: =IF($D10*EBITDA_0*(1+Fee_Transaction)+Financing_Costs+Cash_0-Senior_0-Junior_0>0,(MAX(0,I$6*EBITDA_Exit*(1-Exit_Cost)-Net_Debt_Exit)/($D10*EBITDA_0*(1+Fee_Transaction)+Financing_Costs+Cash_0-Senior_0-Junior_0))^(1/Holding_N)-1,"n/a")
D11: =D10+Step_Multiple | E11: =IF($D11*EBITDA_0*(1+Fee_Transaction)+Financing_Costs+Cash_0-Senior_0-Junior_0>0,(MAX(0,E$6*EBITDA_Exit*(1-Exit_Cost)-Net_Debt_Exit)/($D11*EBITDA_0*(1+Fee_Transaction)+Financing_Costs+Cash_0-Senior_0-Junior_0))^(1/Holding_N)-1,"n/a") | F11: =IF($D11*EBITDA_0*(1+Fee_Transaction)+Financing_Costs+Cash_0-Senior_0-Junior_0>0,(MAX(0,F$6*EBITDA_Exit*(1-Exit_Cost)-Net_Debt_Exit)/($D11*EBITDA_0*(1+Fee_Transaction)+Financing_Costs+Cash_0-Senior_0-Junior_0))^(1/Holding_N)-1,"n/a") | G11: =IF($D11*EBITDA_0*(1+Fee_Transaction)+Financing_Costs+Cash_0-Senior_0-Junior_0>0,(MAX(0,G$6*EBITDA_Exit*(1-Exit_Cost)-Net_Debt_Exit)/($D11*EBITDA_0*(1+Fee_Transaction)+Financing_Costs+Cash_0-Senior_0-Junior_0))^(1/Holding_N)-1,"n/a") | H11: =IF($D11*EBITDA_0*(1+Fee_Transaction)+Financing_Costs+Cash_0-Senior_0-Junior_0>0,(MAX(0,H$6*EBITDA_Exit*(1-Exit_Cost)-Net_Debt_Exit)/($D11*EBITDA_0*(1+Fee_Transaction)+Financing_Costs+Cash_0-Senior_0-Junior_0))^(1/Holding_N)-1,"n/a") | I11: =IF($D11*EBITDA_0*(1+Fee_Transaction)+Financing_Costs+Cash_0-Senior_0-Junior_0>0,(MAX(0,I$6*EBITDA_Exit*(1-Exit_Cost)-Net_Debt_Exit)/($D11*EBITDA_0*(1+Fee_Transaction)+Financing_Costs+Cash_0-Senior_0-Junior_0))^(1/Holding_N)-1,"n/a")
B14: Table 2: IRR by entry multiple (rows) and senior debt in x EBITDA (columns), exit multiple fixed
D15: Entry / debt | E15: =MAX(0,Senior_Multiple-Step_Leverage-Step_Leverage) | F15: =MAX(0,Senior_Multiple-Step_Leverage) | G15: =Senior_Multiple | H15: =Senior_Multiple+Step_Leverage | I15: =Senior_Multiple+Step_Leverage+Step_Leverage
B16: Debt changes interest, tax and repayment. Each column has its own debt schedule (grouped below, click + to show). The exit multiple stays at the base value. | D16: =D7 | E16: =IF($D16*EBITDA_0*(1+Fee_Transaction)+E$23+Cash_0-E$22-Junior_0>0,(MAX(0,Exit_Multiple_Used*EBITDA_Exit*(1-Exit_Cost)-E$24)/($D16*EBITDA_0*(1+Fee_Transaction)+E$23+Cash_0-E$22-Junior_0))^(1/Holding_N)-1,"n/a") | F16: =IF($D16*EBITDA_0*(1+Fee_Transaction)+F$23+Cash_0-F$22-Junior_0>0,(MAX(0,Exit_Multiple_Used*EBITDA_Exit*(1-Exit_Cost)-F$24)/($D16*EBITDA_0*(1+Fee_Transaction)+F$23+Cash_0-F$22-Junior_0))^(1/Holding_N)-1,"n/a") | G16: =IF($D16*EBITDA_0*(1+Fee_Transaction)+G$23+Cash_0-G$22-Junior_0>0,(MAX(0,Exit_Multiple_Used*EBITDA_Exit*(1-Exit_Cost)-G$24)/($D16*EBITDA_0*(1+Fee_Transaction)+G$23+Cash_0-G$22-Junior_0))^(1/Holding_N)-1,"n/a") | H16: =IF($D16*EBITDA_0*(1+Fee_Transaction)+H$23+Cash_0-H$22-Junior_0>0,(MAX(0,Exit_Multiple_Used*EBITDA_Exit*(1-Exit_Cost)-H$24)/($D16*EBITDA_0*(1+Fee_Transaction)+H$23+Cash_0-H$22-Junior_0))^(1/Holding_N)-1,"n/a") | I16: =IF($D16*EBITDA_0*(1+Fee_Transaction)+I$23+Cash_0-I$22-Junior_0>0,(MAX(0,Exit_Multiple_Used*EBITDA_Exit*(1-Exit_Cost)-I$24)/($D16*EBITDA_0*(1+Fee_Transaction)+I$23+Cash_0-I$22-Junior_0))^(1/Holding_N)-1,"n/a")
D17: =D8 | E17: =IF($D17*EBITDA_0*(1+Fee_Transaction)+E$23+Cash_0-E$22-Junior_0>0,(MAX(0,Exit_Multiple_Used*EBITDA_Exit*(1-Exit_Cost)-E$24)/($D17*EBITDA_0*(1+Fee_Transaction)+E$23+Cash_0-E$22-Junior_0))^(1/Holding_N)-1,"n/a") | F17: =IF($D17*EBITDA_0*(1+Fee_Transaction)+F$23+Cash_0-F$22-Junior_0>0,(MAX(0,Exit_Multiple_Used*EBITDA_Exit*(1-Exit_Cost)-F$24)/($D17*EBITDA_0*(1+Fee_Transaction)+F$23+Cash_0-F$22-Junior_0))^(1/Holding_N)-1,"n/a") | G17: =IF($D17*EBITDA_0*(1+Fee_Transaction)+G$23+Cash_0-G$22-Junior_0>0,(MAX(0,Exit_Multiple_Used*EBITDA_Exit*(1-Exit_Cost)-G$24)/($D17*EBITDA_0*(1+Fee_Transaction)+G$23+Cash_0-G$22-Junior_0))^(1/Holding_N)-1,"n/a") | H17: =IF($D17*EBITDA_0*(1+Fee_Transaction)+H$23+Cash_0-H$22-Junior_0>0,(MAX(0,Exit_Multiple_Used*EBITDA_Exit*(1-Exit_Cost)-H$24)/($D17*EBITDA_0*(1+Fee_Transaction)+H$23+Cash_0-H$22-Junior_0))^(1/Holding_N)-1,"n/a") | I17: =IF($D17*EBITDA_0*(1+Fee_Transaction)+I$23+Cash_0-I$22-Junior_0>0,(MAX(0,Exit_Multiple_Used*EBITDA_Exit*(1-Exit_Cost)-I$24)/($D17*EBITDA_0*(1+Fee_Transaction)+I$23+Cash_0-I$22-Junior_0))^(1/Holding_N)-1,"n/a")
D18: =D9 | E18: =IF($D18*EBITDA_0*(1+Fee_Transaction)+E$23+Cash_0-E$22-Junior_0>0,(MAX(0,Exit_Multiple_Used*EBITDA_Exit*(1-Exit_Cost)-E$24)/($D18*EBITDA_0*(1+Fee_Transaction)+E$23+Cash_0-E$22-Junior_0))^(1/Holding_N)-1,"n/a") | F18: =IF($D18*EBITDA_0*(1+Fee_Transaction)+F$23+Cash_0-F$22-Junior_0>0,(MAX(0,Exit_Multiple_Used*EBITDA_Exit*(1-Exit_Cost)-F$24)/($D18*EBITDA_0*(1+Fee_Transaction)+F$23+Cash_0-F$22-Junior_0))^(1/Holding_N)-1,"n/a") | G18: =IF($D18*EBITDA_0*(1+Fee_Transaction)+G$23+Cash_0-G$22-Junior_0>0,(MAX(0,Exit_Multiple_Used*EBITDA_Exit*(1-Exit_Cost)-G$24)/($D18*EBITDA_0*(1+Fee_Transaction)+G$23+Cash_0-G$22-Junior_0))^(1/Holding_N)-1,"n/a") | H18: =IF($D18*EBITDA_0*(1+Fee_Transaction)+H$23+Cash_0-H$22-Junior_0>0,(MAX(0,Exit_Multiple_Used*EBITDA_Exit*(1-Exit_Cost)-H$24)/($D18*EBITDA_0*(1+Fee_Transaction)+H$23+Cash_0-H$22-Junior_0))^(1/Holding_N)-1,"n/a") | I18: =IF($D18*EBITDA_0*(1+Fee_Transaction)+I$23+Cash_0-I$22-Junior_0>0,(MAX(0,Exit_Multiple_Used*EBITDA_Exit*(1-Exit_Cost)-I$24)/($D18*EBITDA_0*(1+Fee_Transaction)+I$23+Cash_0-I$22-Junior_0))^(1/Holding_N)-1,"n/a")
D19: =D10 | E19: =IF($D19*EBITDA_0*(1+Fee_Transaction)+E$23+Cash_0-E$22-Junior_0>0,(MAX(0,Exit_Multiple_Used*EBITDA_Exit*(1-Exit_Cost)-E$24)/($D19*EBITDA_0*(1+Fee_Transaction)+E$23+Cash_0-E$22-Junior_0))^(1/Holding_N)-1,"n/a") | F19: =IF($D19*EBITDA_0*(1+Fee_Transaction)+F$23+Cash_0-F$22-Junior_0>0,(MAX(0,Exit_Multiple_Used*EBITDA_Exit*(1-Exit_Cost)-F$24)/($D19*EBITDA_0*(1+Fee_Transaction)+F$23+Cash_0-F$22-Junior_0))^(1/Holding_N)-1,"n/a") | G19: =IF($D19*EBITDA_0*(1+Fee_Transaction)+G$23+Cash_0-G$22-Junior_0>0,(MAX(0,Exit_Multiple_Used*EBITDA_Exit*(1-Exit_Cost)-G$24)/($D19*EBITDA_0*(1+Fee_Transaction)+G$23+Cash_0-G$22-Junior_0))^(1/Holding_N)-1,"n/a") | H19: =IF($D19*EBITDA_0*(1+Fee_Transaction)+H$23+Cash_0-H$22-Junior_0>0,(MAX(0,Exit_Multiple_Used*EBITDA_Exit*(1-Exit_Cost)-H$24)/($D19*EBITDA_0*(1+Fee_Transaction)+H$23+Cash_0-H$22-Junior_0))^(1/Holding_N)-1,"n/a") | I19: =IF($D19*EBITDA_0*(1+Fee_Transaction)+I$23+Cash_0-I$22-Junior_0>0,(MAX(0,Exit_Multiple_Used*EBITDA_Exit*(1-Exit_Cost)-I$24)/($D19*EBITDA_0*(1+Fee_Transaction)+I$23+Cash_0-I$22-Junior_0))^(1/Holding_N)-1,"n/a")
D20: =D11 | E20: =IF($D20*EBITDA_0*(1+Fee_Transaction)+E$23+Cash_0-E$22-Junior_0>0,(MAX(0,Exit_Multiple_Used*EBITDA_Exit*(1-Exit_Cost)-E$24)/($D20*EBITDA_0*(1+Fee_Transaction)+E$23+Cash_0-E$22-Junior_0))^(1/Holding_N)-1,"n/a") | F20: =IF($D20*EBITDA_0*(1+Fee_Transaction)+F$23+Cash_0-F$22-Junior_0>0,(MAX(0,Exit_Multiple_Used*EBITDA_Exit*(1-Exit_Cost)-F$24)/($D20*EBITDA_0*(1+Fee_Transaction)+F$23+Cash_0-F$22-Junior_0))^(1/Holding_N)-1,"n/a") | G20: =IF($D20*EBITDA_0*(1+Fee_Transaction)+G$23+Cash_0-G$22-Junior_0>0,(MAX(0,Exit_Multiple_Used*EBITDA_Exit*(1-Exit_Cost)-G$24)/($D20*EBITDA_0*(1+Fee_Transaction)+G$23+Cash_0-G$22-Junior_0))^(1/Holding_N)-1,"n/a") | H20: =IF($D20*EBITDA_0*(1+Fee_Transaction)+H$23+Cash_0-H$22-Junior_0>0,(MAX(0,Exit_Multiple_Used*EBITDA_Exit*(1-Exit_Cost)-H$24)/($D20*EBITDA_0*(1+Fee_Transaction)+H$23+Cash_0-H$22-Junior_0))^(1/Holding_N)-1,"n/a") | I20: =IF($D20*EBITDA_0*(1+Fee_Transaction)+I$23+Cash_0-I$22-Junior_0>0,(MAX(0,Exit_Multiple_Used*EBITDA_Exit*(1-Exit_Cost)-I$24)/($D20*EBITDA_0*(1+Fee_Transaction)+I$23+Cash_0-I$22-Junior_0))^(1/Holding_N)-1,"n/a")
B22: Senior debt at closing | C22: CHF m | E22: =E15*EBITDA_0 | F22: =F15*EBITDA_0 | G22: =G15*EBITDA_0 | H22: =H15*EBITDA_0 | I22: =I15*EBITDA_0
B23: Financing costs | C23: CHF m | E23: =Fee_Financing*(E22+Junior_0) | F23: =Fee_Financing*(F22+Junior_0) | G23: =Fee_Financing*(G22+Junior_0) | H23: =Fee_Financing*(H22+Junior_0) | I23: =Fee_Financing*(I22+Junior_0)
B24: Net debt at exit | C24: CHF m | E24: =INDEX($F$41:$L$41,Holding_N) | F24: =INDEX($F$57:$L$57,Holding_N) | G24: =INDEX($F$73:$L$73,Holding_N) | H24: =INDEX($F$89:$L$89,Holding_N) | I24: =INDEX($F$105:$L$105,Holding_N)
B26: Debt schedules for table 2 (one per column, same formulas as the sheet Debt Schedule)
B27: ="Column "&"E"&": senior debt "&FIXED(E$15,1)&"x EBITDA"
B28: Senior debt, opening | C28: CHF m | F28: =E39 | G28: =F39 | H28: =G39 | I28: =H39 | J28: =I39 | K28: =J39 | L28: =K39
B29: Junior debt, opening | C29: CHF m | F29: =E40 | G29: =F40 | H29: =G40 | I29: =H40 | J29: =I40 | K29: =J40 | L29: =K40
B30: Cash, opening | C30: CHF m | F30: =E42 | G30: =F42 | H30: =G42 | I30: =H42 | J30: =I42 | K30: =J42 | L30: =K42
B31: Senior interest | C31: CHF m | F31: ='Debt Schedule'!F8*F28 | G31: ='Debt Schedule'!G8*G28 | H31: ='Debt Schedule'!H8*H28 | I31: ='Debt Schedule'!I8*I28 | J31: ='Debt Schedule'!J8*J28 | K31: ='Debt Schedule'!K8*K28 | L31: ='Debt Schedule'!L8*L28
B32: Junior interest | C32: CHF m | F32: ='Debt Schedule'!F9*F29 | G32: ='Debt Schedule'!G9*G29 | H32: ='Debt Schedule'!H9*H29 | I32: ='Debt Schedule'!I9*I29 | J32: ='Debt Schedule'!J9*J29 | K32: ='Debt Schedule'!K9*K29 | L32: ='Debt Schedule'!L9*L29
B33: of which payment in kind | C33: CHF m | F33: =IF(Junior_Payment="PIK",F32,0) | G33: =IF(Junior_Payment="PIK",G32,0) | H33: =IF(Junior_Payment="PIK",H32,0) | I33: =IF(Junior_Payment="PIK",I32,0) | J33: =IF(Junior_Payment="PIK",J32,0) | K33: =IF(Junior_Payment="PIK",K32,0) | L33: =IF(Junior_Payment="PIK",L32,0)
B34: Interest income | C34: CHF m | F34: =Cash_Rate*MAX(0,F30) | G34: =Cash_Rate*MAX(0,G30) | H34: =Cash_Rate*MAX(0,H30) | I34: =Cash_Rate*MAX(0,I30) | J34: =Cash_Rate*MAX(0,J30) | K34: =Cash_Rate*MAX(0,K30) | L34: =Cash_Rate*MAX(0,L30)
B35: Taxes | C35: CHF m | F35: =Tax_Rate*MAX(0,Operations!F15+F34-IF(Interest_Deductible="Yes",F31+F32,0)) | G35: =Tax_Rate*MAX(0,Operations!G15+G34-IF(Interest_Deductible="Yes",G31+G32,0)) | H35: =Tax_Rate*MAX(0,Operations!H15+H34-IF(Interest_Deductible="Yes",H31+H32,0)) | I35: =Tax_Rate*MAX(0,Operations!I15+I34-IF(Interest_Deductible="Yes",I31+I32,0)) | J35: =Tax_Rate*MAX(0,Operations!J15+J34-IF(Interest_Deductible="Yes",J31+J32,0)) | K35: =Tax_Rate*MAX(0,Operations!K15+K34-IF(Interest_Deductible="Yes",K31+K32,0)) | L35: =Tax_Rate*MAX(0,Operations!L15+L34-IF(Interest_Deductible="Yes",L31+L32,0))
B36: Mandatory amortisation | C36: CHF m | F36: =MIN(F28,Senior_Amort*$E$39) | G36: =MIN(G28,Senior_Amort*$E$39) | H36: =MIN(H28,Senior_Amort*$E$39) | I36: =MIN(I28,Senior_Amort*$E$39) | J36: =MIN(J28,Senior_Amort*$E$39) | K36: =MIN(K28,Senior_Amort*$E$39) | L36: =MIN(L28,Senior_Amort*$E$39)
B37: Cash flow after debt service | C37: CHF m | F37: =Operations!F13-F35-Operations!F16-Operations!F17-(F31+(F32-F33)-F34)-F36 | G37: =Operations!G13-G35-Operations!G16-Operations!G17-(G31+(G32-G33)-G34)-G36 | H37: =Operations!H13-H35-Operations!H16-Operations!H17-(H31+(H32-H33)-H34)-H36 | I37: =Operations!I13-I35-Operations!I16-Operations!I17-(I31+(I32-I33)-I34)-I36 | J37: =Operations!J13-J35-Operations!J16-Operations!J17-(J31+(J32-J33)-J34)-J36 | K37: =Operations!K13-K35-Operations!K16-Operations!K17-(K31+(K32-K33)-K34)-K36 | L37: =Operations!L13-L35-Operations!L16-Operations!L17-(L31+(L32-L33)-L34)-L36
B38: Cash sweep | C38: CHF m | F38: =MIN(F28-F36,Sweep_Share*MAX(0,F30+F37-Min_Cash)) | G38: =MIN(G28-G36,Sweep_Share*MAX(0,G30+G37-Min_Cash)) | H38: =MIN(H28-H36,Sweep_Share*MAX(0,H30+H37-Min_Cash)) | I38: =MIN(I28-I36,Sweep_Share*MAX(0,I30+I37-Min_Cash)) | J38: =MIN(J28-J36,Sweep_Share*MAX(0,J30+J37-Min_Cash)) | K38: =MIN(K28-K36,Sweep_Share*MAX(0,K30+K37-Min_Cash)) | L38: =MIN(L28-L36,Sweep_Share*MAX(0,L30+L37-Min_Cash))
B39: Senior debt, closing | C39: CHF m | E39: =E$22 | F39: =F28-F36-F38 | G39: =G28-G36-G38 | H39: =H28-H36-H38 | I39: =I28-I36-I38 | J39: =J28-J36-J38 | K39: =K28-K36-K38 | L39: =L28-L36-L38
B40: Junior debt, closing | C40: CHF m | E40: =Junior_0 | F40: =F29+F33 | G40: =G29+G33 | H40: =H29+H33 | I40: =I29+I33 | J40: =J29+J33 | K40: =K29+K33 | L40: =L29+L33
B41: Net debt, closing | C41: CHF m | E41: =E39+E40-E42 | F41: =F39+F40-F42 | G41: =G39+G40-G42 | H41: =H39+H40-H42 | I41: =I39+I40-I42 | J41: =J39+J40-J42 | K41: =K39+K40-K42 | L41: =L39+L40-L42
B42: Cash, closing | C42: CHF m | E42: =Cash_0 | F42: =F30+F37-F38 | G42: =G30+G37-G38 | H42: =H30+H37-H38 | I42: =I30+I37-I38 | J42: =J30+J37-J38 | K42: =K30+K37-K38 | L42: =L30+L37-L38
B43: ="Column "&"F"&": senior debt "&FIXED(F$15,1)&"x EBITDA"
B44: Senior debt, opening | C44: CHF m | F44: =E55 | G44: =F55 | H44: =G55 | I44: =H55 | J44: =I55 | K44: =J55 | L44: =K55
B45: Junior debt, opening | C45: CHF m | F45: =E56 | G45: =F56 | H45: =G56 | I45: =H56 | J45: =I56 | K45: =J56 | L45: =K56
B46: Cash, opening | C46: CHF m | F46: =E58 | G46: =F58 | H46: =G58 | I46: =H58 | J46: =I58 | K46: =J58 | L46: =K58
...

Sheet Checks
B1: Checks
B2: =IF(Company_Name="","Company not specified",Company_Name)&" | CHF m unless stated otherwise | Holding period: "&Holding_N&" years | Checks: "&Check_Status
B4: Model state
C5: Inputs complete (1 = yes) | D5: =IF(AND(ISNUMBER(Holding_Period),IF(Entry_Method="Amount",ISNUMBER(Entry_Amount),ISNUMBER(Entry_Multiple)),OR(Exit_Mode<>"Own multiple",ISNUMBER(Exit_Multiple)),IF(Op_Build="EBITDA",AND(ISNUMBER(EBITDA_Input),ISNUMBER(EBITDA_Growth),ISNUMBER(DA_EBITDA),ISNUMBER(Capex_EBITDA)),AND(ISNUMBER(Revenue_0),ISNUMBER(Margin_0),ISNUMBER(DA_Revenue),ISNUMBER(Capex_Revenue))),ISNUMBER(Senior_Multiple),ISNUMBER(Senior_Margin),ISNUMBER(Sweep_Share),ISNUMBER(Tax_Rate),ISNUMBER(Target_IRR),SARON_Count>=Holding_N),1,0)
C6: SARON values within the holding period | D6: =SUMPRODUCT(ISNUMBER(SARON_Path)*(Year_Index<=Holding_N))
B8: Checks
B9: # | C9: Check | D9: Value | E9: Status | F9: What is checked | G9: Message
B10: =1 | C10: Inputs complete | D10: =Inputs_Complete | E10: =IF(Inputs_Complete=1,"OK","MISSING") | F10: Required blue cells on Inputs | G10: =IF(OR(E10="WARNING",E10="ERROR",E10="INFO",E10="MISSING"),"Fill in the blue cells on Inputs (SARON for every year of the holding period)","")
B11: =B10+1 | C11: Holding period valid | D11: =Holding_Period | E11: =IF(Inputs_Complete=0,"n/a",IF(AND(Holding_Period=ROUND(Holding_Period,0),Holding_Period>=Min_Years,Holding_Period<=Max_Years),"OK","ERROR")) | F11: Whole number within the time axis | G11: =IF(OR(E11="WARNING",E11="ERROR",E11="INFO",E11="MISSING"),"Enter a whole number of years from 3 to 7","")
B12: =B11+1 | C12: Switches valid | D12: =IF(OR(Entry_Method="Multiple",Entry_Method="Amount"),0,1)+IF(OR(Exit_Mode="Same as entry",Exit_Mode="Own multiple"),0,1)+IF(OR(Op_Build="EBITDA",Op_Build="Revenue"),0,1)+IF(OR(Scenario="Bear",Scenario="Base",Scenario="Bull"),0,1)+IF(OR(SARON_Floor="Yes",SARON_Floor="No"),0,1)+IF(OR(Junior_Type="Fixed",Junior_Type="SARON"),0,1)+IF(OR(Junior_Payment="Cash",Junior_Payment="PIK"),0,1)+IF(OR(Interest_Deductible="Yes",Interest_Deductible="No"),0,1) | E12: =IF(D12=0,"OK","ERROR") | F12: Switches with a value outside their list | G12: =IF(OR(E12="WARNING",E12="ERROR",E12="INFO",E12="MISSING"),"Choose the switches on Inputs from their lists","")
B13: =B12+1 | C13: EBITDA year 0 positive | D13: =EBITDA_0 | E13: =IF(Inputs_Complete=0,"n/a",IF(EBITDA_0>0,"OK","ERROR")) | F13: EBITDA in CHF m | G13: =IF(OR(E13="WARNING",E13="ERROR",E13="INFO",E13="MISSING"),"Debt is sized on EBITDA: the model needs a positive EBITDA in year 0","")
B14: =B13+1 | C14: Equity of the investor positive | D14: =Equity_In | E14: =IF(Inputs_Complete=0,"n/a",IF(Equity_In>0,"OK","ERROR")) | F14: Equity at closing in CHF m | G14: =IF(OR(E14="WARNING",E14="ERROR",E14="INFO",E14="MISSING"),"Debt and cash cover the whole price: no return can be calculated","")
B15: =B14+1 | C15: Sources equal uses | D15: =Sources_Total-Uses_Total | E15: =IF(Inputs_Complete=0,"n/a",IF(ABS(D15)<=Check_Tolerance*MAX(1,ABS(Uses_Total)),"OK","ERROR")) | F15: Sources less uses | G15: =IF(OR(E15="WARNING",E15="ERROR",E15="INFO",E15="MISSING"),"Sources and uses do not add up: the model has been changed","")
B16: =B15+1 | C16: Debt never negative | D16: =MIN('Debt Schedule'!$F$16:$L$16,'Debt Schedule'!$F$22:$L$22) | E16: =IF(Inputs_Complete=0,"n/a",IF(D16>=-Check_Tolerance,"OK","ERROR")) | F16: Smallest closing balance of senior and junior debt | G16: =IF(OR(E16="WARNING",E16="ERROR",E16="INFO",E16="MISSING"),"A closing debt balance is negative: the model has been changed","")
B17: =B16+1 | C17: Repayment within the senior debt outstanding | D17: =SUMPRODUCT(--('Debt Schedule'!$F$12:$L$12-'Debt Schedule'!$F$14:$L$14-'Debt Schedule'!$F$15:$L$15<-Check_Tolerance)) | E17: =IF(Inputs_Complete=0,"n/a",IF(D17=0,"OK","ERROR")) | F17: Years with more repayment than outstanding | G17: =IF(OR(E17="WARNING",E17="ERROR",E17="INFO",E17="MISSING"),"Repayment exceeds the senior debt outstanding: the model has been changed","")
B18: =B17+1 | C18: Funding gap in the holding period | D18: =Funding_Gap_Year | E18: =IF(Inputs_Complete=0,"n/a",IF(D18=0,"OK","WARNING")) | F18: First year with negative cash (0 = none) | G18: =IF(OR(E18="WARNING",E18="ERROR",E18="INFO",E18="MISSING"),"The cash flow does not cover interest and mandatory amortisation: the investor would need more money (no revolving credit facility in this model)","")
B19: =B18+1 | C19: Equity value at exit above zero | D19: =Equity_Exit_Raw | E19: =IF(Inputs_Complete=0,"n/a",IF(D19>0,"OK","WARNING")) | F19: Exit value less net debt | G19: =IF(OR(E19="WARNING",E19="ERROR",E19="INFO",E19="MISSING"),"The debt at exit exceeds the exit value: the investor loses the whole equity (MOIC 0.00x, IRR -100%). The rest of the loss is borne by the lenders.","")
B20: =B19+1 | C20: Attribution adds up to the gain | D20: =Attribution_Sum-Investor_Gain | E20: =IF(Inputs_Complete=0,"n/a",IF(ABS(D20)<=Check_Tolerance*MAX(1,ABS(Equity_In)),"OK","ERROR")) | F20: Sum of the five parts less the gain | G20: =IF(OR(E20="WARNING",E20="ERROR",E20="INFO",E20="MISSING"),"The attribution does not add up: the model has been changed","")
B21: =B20+1 | C21: IRR and MOIC consistent | D21: =IF(ISNUMBER(IRR),(1+IRR)^Holding_N-MOIC,0) | E21: =IF(Inputs_Complete=0,"n/a",IF(ABS(D21)<=Check_Tolerance*MAX(1,ABS(MOIC)),"OK","ERROR")) | F21: (1 + IRR) ^ holding period less MOIC | G21: =IF(OR(E21="WARNING",E21="ERROR",E21="INFO",E21="MISSING"),"IRR and MOIC do not match: the model has been changed","")
B22: =B21+1 | C22: IRR function gives the same IRR | D22: =IF(Equity_Exit>0,IRR(Investor_Cash_Flows)-IRR,0) | E22: =IF(Inputs_Complete=0,"n/a",IF(ABS(D22)<=IRR_Tolerance,"OK","ERROR")) | F22: Function IRR on the cash flows less the closed formula | G22: =IF(OR(E22="WARNING",E22="ERROR",E22="INFO",E22="MISSING"),"The function IRR gives another result: the model has been changed","")
B23: =B22+1 | C23: Maximum price gives the target IRR | D23: =IF(ISNUMBER(Max_EV),(Equity_Exit/(Max_EV*(1+Fee_Transaction)+Financing_Costs+Cash_0-Senior_0-Junior_0))^(1/Holding_N)-1-Target_IRR,0) | E23: =IF(Inputs_Complete=0,"n/a",IF(ABS(D23)<=Check_Tolerance*MAX(1,ABS(Target_IRR)),"OK","ERROR")) | F23: IRR at the maximum price less the target IRR | G23: =IF(OR(E23="WARNING",E23="ERROR",E23="INFO",E23="MISSING"),"The maximum price does not give the target IRR: the model has been changed","")
B24: =B23+1 | C24: Maximum price exists | D24: =Max_Multiple | E24: =IF(Inputs_Complete=0,"n/a",IF(ISNUMBER(Max_Multiple),"OK","WARNING")) | F24: Maximum entry multiple | G24: =IF(OR(E24="WARNING",E24="ERROR",E24="INFO",E24="MISSING"),"No price reaches the target IRR with these assumptions","")
B25: =B24+1 | C25: Centre of the sensitivities equals the base case | D25: =IF(ISNUMBER(IRR),ABS(INDEX(Sens_Exit,3,3)-IRR)+ABS(INDEX(Sens_Debt,3,3)-IRR)+ABS(Sensitivities!G24-Net_Debt_Exit),0) | E25: =IF(Inputs_Complete=0,"n/a",IF(D25<=Check_Tolerance*MAX(1,ABS(Net_Debt_Exit)),"OK","ERROR")) | F25: Differences of both tables and of the middle debt schedule | G25: =IF(OR(E25="WARNING",E25="ERROR",E25="INFO",E25="MISSING"),"The sensitivities do not match the base case: the model has been changed","")
B26: =B25+1 | C26: Interest rate below zero | D26: =SUMPRODUCT(('Debt Schedule'!$F$8:$L$8<0)*(Senior_0>0))+SUMPRODUCT(('Debt Schedule'!$F$9:$L$9<0)*(Junior_0>0)) | E26: =IF(Inputs_Complete=0,"n/a",IF(D26=0,"OK","INFO")) | F26: Years with a negative interest rate on debt | G26: =IF(OR(E26="WARNING",E26="ERROR",E26="INFO",E26="MISSING"),"A negative SARON without floor gives a negative interest rate in some years","")
B27: =B26+1 | C27: Exit multiple above entry multiple | D27: =Exit_Multiple_Used-Entry_Multiple_Used | E27: =IF(Inputs_Complete=0,"n/a",IF(D27<=0,"OK","INFO")) | F27: Exit less entry multiple | G27: =IF(OR(E27="WARNING",E27="ERROR",E27="INFO",E27="MISSING"),"Part of the return comes from a higher multiple at exit (see Where the return comes from on Returns)","")
B28: =B27+1 | C28: No error values in the model | D28: =SUMPRODUCT(--ISERROR(Transaction!E5:F24))+SUMPRODUCT(--ISERROR(Operations!E4:L17))+SUMPRODUCT(--ISERROR('Debt Schedule'!E4:L49))+SUMPRODUCT(--ISERROR(Returns!E5:E38))+SUMPRODUCT(--ISERROR(Returns!B41))+SUMPRODUCT(--ISERROR(Returns!E46:L46))+SUMPRODUCT(--ISERROR(Sensitivities!D6:I24))+SUMPRODUCT(--ISERROR(Sens_Schedules)) | E28: =IF(D28=0,"OK","ERROR") | F28: Cells with error values | G28: =IF(OR(E28="WARNING",E28="ERROR",E28="INFO",E28="MISSING"),"Some cells show error values","")
B30: Summary
C31: Errors | D31: =COUNTIF(Check_Statuses,"ERROR")
C32: Warnings | D32: =COUNTIF(Check_Statuses,"WARNING")
C33: Overall status | D33: =IF(Check_Errors>0,Check_Errors&IF(Check_Errors=1," check failed"," checks failed"),IF(Inputs_Complete=0,"Inputs missing",IF(Check_Warnings=0,"All checks OK","All checks OK, "&Check_Warnings&IF(Check_Warnings=1," warning"," warnings"))))

Sheet Settings
B1: Settings
B2: =IF(Company_Name="","Company not specified",Company_Name)&" | CHF m unless stated otherwise | Holding period: "&Holding_N&" years | Checks: "&Check_Status
B4: Parameters
B5: Shortest holding period | C5: 3 | E5: The website allows 3 to 7 years. The time axis of the model has 7 years.
B6: Longest holding period | C6: 7 | E6: Length of the time axis on Operations and Debt Schedule
B7: Step of the multiples in the sensitivities | C7: 1 | E7: Entry and exit multiple, as on the website
B8: Step of the senior debt in the sensitivities | C8: 0.5 | E8: Senior debt as a multiple of EBITDA, as on the website. Never below zero.
B9: Check tolerance | C9: 1e-09 | E9: Largest relative difference accepted by the checks
B10: Tolerance of the IRR function | C10: 1e-06 | E10: The function IRR searches step by step and is less precise than the closed formula. Used only for the cross-check.
